<?xml version="1.0" encoding="utf-8"?>
<!-- =================================================================================== -->
<!-- |    This document was autogenerated by xacro from omtp_factory.xacro             | -->
<!-- |    EDITING THIS FILE BY HAND IS NOT RECOMMENDED                                 | -->
<!-- =================================================================================== -->
<robot name="omtp">
  <!-- ==================================================== -->
  <!-- INITIAL SETUP OF WORLD LINK AND WORLD_INTERFACE LINK -->
  <!-- ==================================================== -->
  <!-- world -->
  <link name="world"/>
  <!-- world_interface. Makes it convenient to move the whole environment according to the world origin -->
  <link name="world_interface"/>
  <!-- world<->world_interface joint -->
  <joint name="world_interface_to_world" type="fixed">
    <parent link="world"/>
    <child link="world_interface"/>
  </joint>
  <!-- Links -->
  <link name="fib14">
    <visual>
      <geometry>
        <mesh filename="package://aau_lab_ros_models/meshes/fib14/fib14.dae"/>
      </geometry>
    </visual>
    <collision>
      <geometry>
        <mesh filename="package://aau_lab_ros_models/meshes/fib14/fib14.dae"/>
      </geometry>
    </collision>
    <inertial>
      <inertia ixx="1.0" ixy="0" ixz="0" iyy="1.0" iyz="0" izz="1.0"/>
      <mass value="100"/>
    </inertial>
  </link>
  <joint name="fib14_to_world_interface" type="fixed">
    <parent link="world_interface"/>
    <child link="fib14"/>
    <origin rpy="0 0 0" xyz="0 0 0"/>
  </joint>
  <joint name="panda_1_virtual_joint" type="fixed">
    <parent link="robot1_pedestal_link"/>
    <child link="panda_1_link0"/>
    <origin rpy="0 0 0" xyz="0 0 0.95"/>
  </joint>
  <link name="panda_1_link0">
    <visual>
      <geometry>
        <mesh filename="package://franka_description/meshes/visual/link0.dae"/>
      </geometry>
    </visual>
    <collision>
      <origin rpy="0 0 0" xyz="0 0 -0.1915"/>
      <geometry>
        <cylinder length="0.2830" radius="0.09"/>
      </geometry>
    </collision>
    <collision>
      <origin rpy="0 0 0" xyz="0 0 -0.333"/>
      <geometry>
        <sphere radius="0.09"/>
      </geometry>
    </collision>
    <collision>
      <origin rpy="0 0 0" xyz="0 0 -0.05"/>
      <geometry>
        <sphere radius="0.09"/>
      </geometry>
    </collision>
  </link>
  <link name="panda_1_link1">
    <visual>
      <geometry>
        <mesh filename="package://franka_description/meshes/visual/link1.dae"/>
      </geometry>
    </visual>
    <collision>
      <origin rpy="0 0 0" xyz="0 0 -0.1915"/>
      <geometry>
        <cylinder length="0.2830" radius="0.09"/>
      </geometry>
    </collision>
    <collision>
      <origin rpy="0 0 0" xyz="0 0 -0.333"/>
      <geometry>
        <sphere radius="0.09"/>
      </geometry>
    </collision>
    <collision>
      <origin rpy="0 0 0" xyz="0 0 -0.05"/>
      <geometry>
        <sphere radius="0.09"/>
      </geometry>
    </collision>
  </link>
  <link name="panda_1_link2">
    <visual>
      <geometry>
        <mesh filename="package://franka_description/meshes/visual/link2.dae"/>
      </geometry>
    </visual>
    <collision>
      <origin rpy="0 0 0" xyz="0 0 0"/>
      <geometry>
        <cylinder length="0.12" radius="0.09"/>
      </geometry>
    </collision>
    <collision>
      <origin rpy="0 0 0" xyz="0 0 -0.06"/>
      <geometry>
        <sphere radius="0.09"/>
      </geometry>
    </collision>
    <collision>
      <origin rpy="0 0 0" xyz="0 0 0.06"/>
      <geometry>
        <sphere radius="0.09"/>
      </geometry>
    </collision>
  </link>
  <link name="panda_1_link3">
    <visual>
      <geometry>
        <mesh filename="package://franka_description/meshes/visual/link3.dae"/>
      </geometry>
    </visual>
    <collision>
      <origin rpy="0 0 0" xyz="0 0 -0.145"/>
      <geometry>
        <cylinder length="0.15" radius="0.09"/>
      </geometry>
    </collision>
    <collision>
      <origin rpy="0 0 0" xyz="0 0 -0.22"/>
      <geometry>
        <sphere radius="0.09"/>
      </geometry>
    </collision>
    <collision>
      <origin rpy="0 0 0" xyz="0 0 -0.07"/>
      <geometry>
        <sphere radius="0.09"/>
      </geometry>
    </collision>
  </link>
  <link name="panda_1_link4">
    <visual>
      <geometry>
        <mesh filename="package://franka_description/meshes/visual/link4.dae"/>
      </geometry>
    </visual>
    <collision>
      <origin rpy="0 0 0" xyz="0 0 0"/>
      <geometry>
        <cylinder length="0.12" radius="0.09"/>
      </geometry>
    </collision>
    <collision>
      <origin rpy="0 0 0" xyz="0 0 0.06"/>
      <geometry>
        <sphere radius="0.09"/>
      </geometry>
    </collision>
    <collision>
      <origin rpy="0 0 0" xyz="0 0 -0.06"/>
      <geometry>
        <sphere radius="0.09"/>
      </geometry>
    </collision>
  </link>
  <link name="panda_1_link5">
    <visual>
      <geometry>
        <mesh filename="package://franka_description/meshes/visual/link5.dae"/>
      </geometry>
    </visual>
    <collision>
      <origin rpy="0 0 0" xyz="0 0 -0.26"/>
      <geometry>
        <cylinder length="0.1" radius="0.09"/>
      </geometry>
    </collision>
    <collision>
      <origin rpy="0 0 0" xyz="0 0 -0.31"/>
      <geometry>
        <sphere radius="0.09"/>
      </geometry>
    </collision>
    <collision>
      <origin rpy="0 0 0" xyz="0 0 -0.21"/>
      <geometry>
        <sphere radius="0.09"/>
      </geometry>
    </collision>
    <collision>
      <origin rpy="0 0 0" xyz="0 0.08 -0.13"/>
      <geometry>
        <cylinder length="0.14" radius="0.055"/>
      </geometry>
    </collision>
    <collision>
      <origin rpy="0 0 0" xyz="0 0.08 -0.06"/>
      <geometry>
        <sphere radius="0.055"/>
      </geometry>
    </collision>
    <collision>
      <origin rpy="0 0 0" xyz="0 0.08 -0.20"/>
      <geometry>
        <sphere radius="0.055"/>
      </geometry>
    </collision>
  </link>
  <link name="panda_1_link6">
    <visual>
      <geometry>
        <mesh filename="package://franka_description/meshes/visual/link6.dae"/>
      </geometry>
    </visual>
    <collision>
      <origin rpy="0 0 0" xyz="0 0 -0.03"/>
      <geometry>
        <cylinder length="0.08" radius="0.08"/>
      </geometry>
    </collision>
    <collision>
      <origin rpy="0 0 0" xyz="0 0 0.01"/>
      <geometry>
        <sphere radius="0.08"/>
      </geometry>
    </collision>
    <collision>
      <origin rpy="0 0 0" xyz="0 0 -0.07"/>
      <geometry>
        <sphere radius="0.08"/>
      </geometry>
    </collision>
  </link>
  <link name="panda_1_link7">
    <visual>
      <geometry>
        <mesh filename="package://franka_description/meshes/visual/link7.dae"/>
      </geometry>
    </visual>
    <collision>
      <origin rpy="0 0 0" xyz="0 0 0.01"/>
      <geometry>
        <cylinder length="0.14" radius="0.07"/>
      </geometry>
    </collision>
    <collision>
      <origin rpy="0 0 0" xyz="0 0 0.08"/>
      <geometry>
        <sphere radius="0.07"/>
      </geometry>
    </collision>
    <collision>
      <origin rpy="0 0 0" xyz="0 0 -0.06"/>
      <geometry>
        <sphere radius="0.07"/>
      </geometry>
    </collision>
  </link>
  <link name="panda_1_link8">
    <collision>
      <origin rpy="3.14159265359 1.57079632679 1.57079632679" xyz="0.0424 0.0424 -0.0250"/>
      <geometry>
        <cylinder length="0.01" radius="0.06"/>
      </geometry>
    </collision>
    <collision>
      <origin rpy="0 0 0" xyz="0.0424 0.0424 -0.02"/>
      <geometry>
        <sphere radius="0.06"/>
      </geometry>
    </collision>
    <collision>
      <origin rpy="0 0 0" xyz="0.0424 0.0424 -0.03"/>
      <geometry>
        <sphere radius="0.06"/>
      </geometry>
    </collision>
  </link>
  <joint name="panda_1_joint1" type="revolute">
    <safety_controller k_position="100.0" k_velocity="40.0" soft_lower_limit="-2.8973" soft_upper_limit="2.8973"/>
    <origin rpy="0 0 0" xyz="0 0 0.333"/>
    <parent link="panda_1_link0"/>
    <child link="panda_1_link1"/>
    <limit effort="87" lower="-2.8973" upper="2.8973" velocity="2.175"/>
    <axis xyz="0 0 1"/>
    <dynamics damping="1.0"/>
  </joint>
  <joint name="panda_1_joint2" type="revolute">
    <safety_controller k_position="100.0" k_velocity="40.0" soft_lower_limit="-1.7628" soft_upper_limit="1.7628"/>
    <origin rpy="-1.57079632679 0 0" xyz="0 0 0"/>
    <parent link="panda_1_link1"/>
    <child link="panda_1_link2"/>
    <limit effort="87" lower="-1.7628" upper="1.7628" velocity="2.175"/>
    <axis xyz="0 0 1"/>
    <dynamics damping="1.0"/>
  </joint>
  <joint name="panda_1_joint3" type="revolute">
    <safety_controller k_position="100.0" k_velocity="40.0" soft_lower_limit="-2.8973" soft_upper_limit="2.8973"/>
    <origin rpy="1.57079632679 0 0" xyz="0 -0.316 0"/>
    <parent link="panda_1_link2"/>
    <child link="panda_1_link3"/>
    <limit effort="87" lower="-2.8973" upper="2.8973" velocity="2.175"/>
    <axis xyz="0 0 1"/>
    <dynamics damping="1.0"/>
  </joint>
  <joint name="panda_1_joint4" type="revolute">
    <safety_controller k_position="100.0" k_velocity="40.0" soft_lower_limit="-3.0718" soft_upper_limit="-0.0698"/>
    <origin rpy="1.57079632679 0 0" xyz="0.0825 0 0"/>
    <parent link="panda_1_link3"/>
    <child link="panda_1_link4"/>
    <limit effort="87" lower="-3.0718" upper="-0.0698" velocity="2.175"/>
    <axis xyz="0 0 1"/>
    <dynamics damping="1.0"/>
  </joint>
  <joint name="panda_1_joint5" type="revolute">
    <safety_controller k_position="100.0" k_velocity="40.0" soft_lower_limit="-2.8973" soft_upper_limit="2.8973"/>
    <origin rpy="-1.57079632679 0 0" xyz="-0.0825 0.384 0"/>
    <parent link="panda_1_link4"/>
    <child link="panda_1_link5"/>
    <limit effort="12" lower="-2.8973" upper="2.8973" velocity="2.61"/>
    <axis xyz="0 0 1"/>
    <dynamics damping="1.0"/>
  </joint>
  <joint name="panda_1_joint6" type="revolute">
    <safety_controller k_position="100.0" k_velocity="40.0" soft_lower_limit="-0.0175" soft_upper_limit="3.7525"/>
    <origin rpy="1.57079632679 0 0" xyz="0 0 0"/>
    <parent link="panda_1_link5"/>
    <child link="panda_1_link6"/>
    <limit effort="12" lower="-0.0175" upper="3.7525" velocity="2.61"/>
    <axis xyz="0 0 1"/>
    <dynamics damping="1.0"/>
  </joint>
  <joint name="panda_1_joint7" type="revolute">
    <safety_controller k_position="100.0" k_velocity="40.0" soft_lower_limit="-2.8973" soft_upper_limit="2.8973"/>
    <origin rpy="1.57079632679 0 0" xyz="0.088 0 0"/>
    <parent link="panda_1_link6"/>
    <child link="panda_1_link7"/>
    <limit effort="12" lower="-2.8973" upper="2.8973" velocity="2.61"/>
    <axis xyz="0 0 1"/>
    <dynamics damping="1.0"/>
  </joint>
  <joint name="panda_1_joint8" type="fixed">
    <origin rpy="0 0 0" xyz="0 0 0.107"/>
    <parent link="panda_1_link7"/>
    <child link="panda_1_link8"/>
    <axis xyz="0 0 0"/>
    <dynamics damping="1.0"/>
  </joint>
  <joint name="panda_1_hand_joint" type="fixed">
    <parent link="panda_1_link8"/>
    <child link="panda_1_hand"/>
    <origin rpy="0 0 -0.785398163397" xyz="0 0 0"/>
  </joint>
  <link name="panda_1_hand">
    <visual>
      <geometry>
        <mesh filename="package://franka_description/meshes/visual/hand.dae"/>
      </geometry>
    </visual>
    <collision>
      <origin rpy="0 1.57079632679 1.57079632679" xyz="0 0 0.04"/>
      <geometry>
        <cylinder length="0.1" radius="0.07"/>
      </geometry>
    </collision>
    <collision>
      <origin rpy="0 0 0" xyz="0 -0.05 0.04"/>
      <geometry>
        <sphere radius="0.07"/>
      </geometry>
    </collision>
    <collision>
      <origin rpy="0 0 0" xyz="0 0.05 0.04"/>
      <geometry>
        <sphere radius="0.07"/>
      </geometry>
    </collision>
    <collision>
      <origin rpy="0 1.57079632679 1.57079632679" xyz="0 0 0.1"/>
      <geometry>
        <cylinder length="0.1" radius="0.05"/>
      </geometry>
    </collision>
    <collision>
      <origin rpy="0 0 0" xyz="0 -0.05 0.1"/>
      <geometry>
        <sphere radius="0.05"/>
      </geometry>
    </collision>
    <collision>
      <origin rpy="0 0 0" xyz="0 0.05 0.1"/>
      <geometry>
        <sphere radius="0.05"/>
      </geometry>
    </collision>
  </link>
  <link name="panda_1_leftfinger">
    <visual>
      <geometry>
        <mesh filename="package://franka_description/meshes/visual/finger.dae"/>
      </geometry>
    </visual>
  </link>
  <link name="panda_1_rightfinger">
    <visual>
      <origin rpy="0 0 3.14159265359" xyz="0 0 0"/>
      <geometry>
        <mesh filename="package://franka_description/meshes/visual/finger.dae"/>
      </geometry>
    </visual>
  </link>
  <joint name="panda_1_finger_joint1" type="prismatic">
    <parent link="panda_1_hand"/>
    <child link="panda_1_leftfinger"/>
    <origin rpy="0 0 0" xyz="0 0 0.0584"/>
    <axis xyz="0 1 0"/>
    <limit effort="150" lower="0.0" upper="0.04" velocity="0.2"/>
  </joint>
  <joint name="panda_1_finger_joint2" type="prismatic">
    <parent link="panda_1_hand"/>
    <child link="panda_1_rightfinger"/>
    <origin rpy="0 0 0" xyz="0 0 0.0584"/>
    <axis xyz="0 -1 0"/>
    <limit effort="150" lower="0.0" upper="0.04" velocity="0.2"/>
    <mimic joint="panda_1_finger_joint1"/>
  </joint>
  <joint name="panda_3_virtual_joint" type="fixed">
    <parent link="robot2_pedestal_link"/>
    <child link="panda_3_link0"/>
    <origin rpy="0 0 0" xyz="0 0 0.95"/>
  </joint>
  <link name="panda_3_link0">
    <visual>
      <geometry>
        <mesh filename="package://franka_description/meshes/visual/link0.dae"/>
      </geometry>
    </visual>
    <collision>
      <origin rpy="0 0 0" xyz="0 0 -0.1915"/>
      <geometry>
        <cylinder length="0.2830" radius="0.09"/>
      </geometry>
    </collision>
    <collision>
      <origin rpy="0 0 0" xyz="0 0 -0.333"/>
      <geometry>
        <sphere radius="0.09"/>
      </geometry>
    </collision>
    <collision>
      <origin rpy="0 0 0" xyz="0 0 -0.05"/>
      <geometry>
        <sphere radius="0.09"/>
      </geometry>
    </collision>
  </link>
  <link name="panda_3_link1">
    <visual>
      <geometry>
        <mesh filename="package://franka_description/meshes/visual/link1.dae"/>
      </geometry>
    </visual>
    <collision>
      <origin rpy="0 0 0" xyz="0 0 -0.1915"/>
      <geometry>
        <cylinder length="0.2830" radius="0.09"/>
      </geometry>
    </collision>
    <collision>
      <origin rpy="0 0 0" xyz="0 0 -0.333"/>
      <geometry>
        <sphere radius="0.09"/>
      </geometry>
    </collision>
    <collision>
      <origin rpy="0 0 0" xyz="0 0 -0.05"/>
      <geometry>
        <sphere radius="0.09"/>
      </geometry>
    </collision>
  </link>
  <link name="panda_3_link2">
    <visual>
      <geometry>
        <mesh filename="package://franka_description/meshes/visual/link2.dae"/>
      </geometry>
    </visual>
    <collision>
      <origin rpy="0 0 0" xyz="0 0 0"/>
      <geometry>
        <cylinder length="0.12" radius="0.09"/>
      </geometry>
    </collision>
    <collision>
      <origin rpy="0 0 0" xyz="0 0 -0.06"/>
      <geometry>
        <sphere radius="0.09"/>
      </geometry>
    </collision>
    <collision>
      <origin rpy="0 0 0" xyz="0 0 0.06"/>
      <geometry>
        <sphere radius="0.09"/>
      </geometry>
    </collision>
  </link>
  <link name="panda_3_link3">
    <visual>
      <geometry>
        <mesh filename="package://franka_description/meshes/visual/link3.dae"/>
      </geometry>
    </visual>
    <collision>
      <origin rpy="0 0 0" xyz="0 0 -0.145"/>
      <geometry>
        <cylinder length="0.15" radius="0.09"/>
      </geometry>
    </collision>
    <collision>
      <origin rpy="0 0 0" xyz="0 0 -0.22"/>
      <geometry>
        <sphere radius="0.09"/>
      </geometry>
    </collision>
    <collision>
      <origin rpy="0 0 0" xyz="0 0 -0.07"/>
      <geometry>
        <sphere radius="0.09"/>
      </geometry>
    </collision>
  </link>
  <link name="panda_3_link4">
    <visual>
      <geometry>
        <mesh filename="package://franka_description/meshes/visual/link4.dae"/>
      </geometry>
    </visual>
    <collision>
      <origin rpy="0 0 0" xyz="0 0 0"/>
      <geometry>
        <cylinder length="0.12" radius="0.09"/>
      </geometry>
    </collision>
    <collision>
      <origin rpy="0 0 0" xyz="0 0 0.06"/>
      <geometry>
        <sphere radius="0.09"/>
      </geometry>
    </collision>
    <collision>
      <origin rpy="0 0 0" xyz="0 0 -0.06"/>
      <geometry>
        <sphere radius="0.09"/>
      </geometry>
    </collision>
  </link>
  <link name="panda_3_link5">
    <visual>
      <geometry>
        <mesh filename="package://franka_description/meshes/visual/link5.dae"/>
      </geometry>
    </visual>
    <collision>
      <origin rpy="0 0 0" xyz="0 0 -0.26"/>
      <geometry>
        <cylinder length="0.1" radius="0.09"/>
      </geometry>
    </collision>
    <collision>
      <origin rpy="0 0 0" xyz="0 0 -0.31"/>
      <geometry>
        <sphere radius="0.09"/>
      </geometry>
    </collision>
    <collision>
      <origin rpy="0 0 0" xyz="0 0 -0.21"/>
      <geometry>
        <sphere radius="0.09"/>
      </geometry>
    </collision>
    <collision>
      <origin rpy="0 0 0" xyz="0 0.08 -0.13"/>
      <geometry>
        <cylinder length="0.14" radius="0.055"/>
      </geometry>
    </collision>
    <collision>
      <origin rpy="0 0 0" xyz="0 0.08 -0.06"/>
      <geometry>
        <sphere radius="0.055"/>
      </geometry>
    </collision>
    <collision>
      <origin rpy="0 0 0" xyz="0 0.08 -0.20"/>
      <geometry>
        <sphere radius="0.055"/>
      </geometry>
    </collision>
  </link>
  <link name="panda_3_link6">
    <visual>
      <geometry>
        <mesh filename="package://franka_description/meshes/visual/link6.dae"/>
      </geometry>
    </visual>
    <collision>
      <origin rpy="0 0 0" xyz="0 0 -0.03"/>
      <geometry>
        <cylinder length="0.08" radius="0.08"/>
      </geometry>
    </collision>
    <collision>
      <origin rpy="0 0 0" xyz="0 0 0.01"/>
      <geometry>
        <sphere radius="0.08"/>
      </geometry>
    </collision>
    <collision>
      <origin rpy="0 0 0" xyz="0 0 -0.07"/>
      <geometry>
        <sphere radius="0.08"/>
      </geometry>
    </collision>
  </link>
  <link name="panda_3_link7">
    <visual>
      <geometry>
        <mesh filename="package://franka_description/meshes/visual/link7.dae"/>
      </geometry>
    </visual>
    <collision>
      <origin rpy="0 0 0" xyz="0 0 0.01"/>
      <geometry>
        <cylinder length="0.14" radius="0.07"/>
      </geometry>
    </collision>
    <collision>
      <origin rpy="0 0 0" xyz="0 0 0.08"/>
      <geometry>
        <sphere radius="0.07"/>
      </geometry>
    </collision>
    <collision>
      <origin rpy="0 0 0" xyz="0 0 -0.06"/>
      <geometry>
        <sphere radius="0.07"/>
      </geometry>
    </collision>
  </link>
  <link name="panda_3_link8">
    <collision>
      <origin rpy="3.14159265359 1.57079632679 1.57079632679" xyz="0.0424 0.0424 -0.0250"/>
      <geometry>
        <cylinder length="0.01" radius="0.06"/>
      </geometry>
    </collision>
    <collision>
      <origin rpy="0 0 0" xyz="0.0424 0.0424 -0.02"/>
      <geometry>
        <sphere radius="0.06"/>
      </geometry>
    </collision>
    <collision>
      <origin rpy="0 0 0" xyz="0.0424 0.0424 -0.03"/>
      <geometry>
        <sphere radius="0.06"/>
      </geometry>
    </collision>
  </link>
  <joint name="panda_3_joint1" type="revolute">
    <safety_controller k_position="100.0" k_velocity="40.0" soft_lower_limit="-2.8973" soft_upper_limit="2.8973"/>
    <origin rpy="0 0 0" xyz="0 0 0.333"/>
    <parent link="panda_3_link0"/>
    <child link="panda_3_link1"/>
    <limit effort="87" lower="-2.8973" upper="2.8973" velocity="2.175"/>
    <axis xyz="0 0 1"/>
    <dynamics damping="1.0"/>
  </joint>
  <joint name="panda_3_joint2" type="revolute">
    <safety_controller k_position="100.0" k_velocity="40.0" soft_lower_limit="-1.7628" soft_upper_limit="1.7628"/>
    <origin rpy="-1.57079632679 0 0" xyz="0 0 0"/>
    <parent link="panda_3_link1"/>
    <child link="panda_3_link2"/>
    <limit effort="87" lower="-1.7628" upper="1.7628" velocity="2.175"/>
    <axis xyz="0 0 1"/>
    <dynamics damping="1.0"/>
  </joint>
  <joint name="panda_3_joint3" type="revolute">
    <safety_controller k_position="100.0" k_velocity="40.0" soft_lower_limit="-2.8973" soft_upper_limit="2.8973"/>
    <origin rpy="1.57079632679 0 0" xyz="0 -0.316 0"/>
    <parent link="panda_3_link2"/>
    <child link="panda_3_link3"/>
    <limit effort="87" lower="-2.8973" upper="2.8973" velocity="2.175"/>
    <axis xyz="0 0 1"/>
    <dynamics damping="1.0"/>
  </joint>
  <joint name="panda_3_joint4" type="revolute">
    <safety_controller k_position="100.0" k_velocity="40.0" soft_lower_limit="-3.0718" soft_upper_limit="-0.0698"/>
    <origin rpy="1.57079632679 0 0" xyz="0.0825 0 0"/>
    <parent link="panda_3_link3"/>
    <child link="panda_3_link4"/>
    <limit effort="87" lower="-3.0718" upper="-0.0698" velocity="2.175"/>
    <axis xyz="0 0 1"/>
    <dynamics damping="1.0"/>
  </joint>
  <joint name="panda_3_joint5" type="revolute">
    <safety_controller k_position="100.0" k_velocity="40.0" soft_lower_limit="-2.8973" soft_upper_limit="2.8973"/>
    <origin rpy="-1.57079632679 0 0" xyz="-0.0825 0.384 0"/>
    <parent link="panda_3_link4"/>
    <child link="panda_3_link5"/>
    <limit effort="12" lower="-2.8973" upper="2.8973" velocity="2.61"/>
    <axis xyz="0 0 1"/>
    <dynamics damping="1.0"/>
  </joint>
  <joint name="panda_3_joint6" type="revolute">
    <safety_controller k_position="100.0" k_velocity="40.0" soft_lower_limit="-0.0175" soft_upper_limit="3.7525"/>
    <origin rpy="1.57079632679 0 0" xyz="0 0 0"/>
    <parent link="panda_3_link5"/>
    <child link="panda_3_link6"/>
    <limit effort="12" lower="-0.0175" upper="3.7525" velocity="2.61"/>
    <axis xyz="0 0 1"/>
    <dynamics damping="1.0"/>
  </joint>
  <joint name="panda_3_joint7" type="revolute">
    <safety_controller k_position="100.0" k_velocity="40.0" soft_lower_limit="-2.8973" soft_upper_limit="2.8973"/>
    <origin rpy="1.57079632679 0 0" xyz="0.088 0 0"/>
    <parent link="panda_3_link6"/>
    <child link="panda_3_link7"/>
    <limit effort="12" lower="-2.8973" upper="2.8973" velocity="2.61"/>
    <axis xyz="0 0 1"/>
    <dynamics damping="1.0"/>
  </joint>
  <joint name="panda_3_joint8" type="fixed">
    <origin rpy="0 0 0" xyz="0 0 0.107"/>
    <parent link="panda_3_link7"/>
    <child link="panda_3_link8"/>
    <axis xyz="0 0 0"/>
    <dynamics damping="1.0"/>
  </joint>
  <joint name="panda_3_hand_joint" type="fixed">
    <parent link="panda_3_link8"/>
    <child link="panda_3_hand"/>
    <origin rpy="0 0 -0.785398163397" xyz="0 0 0"/>
  </joint>
  <link name="panda_3_hand">
    <visual>
      <geometry>
        <mesh filename="package://franka_description/meshes/visual/hand.dae"/>
      </geometry>
    </visual>
    <collision>
      <origin rpy="0 1.57079632679 1.57079632679" xyz="0 0 0.04"/>
      <geometry>
        <cylinder length="0.1" radius="0.07"/>
      </geometry>
    </collision>
    <collision>
      <origin rpy="0 0 0" xyz="0 -0.05 0.04"/>
      <geometry>
        <sphere radius="0.07"/>
      </geometry>
    </collision>
    <collision>
      <origin rpy="0 0 0" xyz="0 0.05 0.04"/>
      <geometry>
        <sphere radius="0.07"/>
      </geometry>
    </collision>
    <collision>
      <origin rpy="0 1.57079632679 1.57079632679" xyz="0 0 0.1"/>
      <geometry>
        <cylinder length="0.1" radius="0.05"/>
      </geometry>
    </collision>
    <collision>
      <origin rpy="0 0 0" xyz="0 -0.05 0.1"/>
      <geometry>
        <sphere radius="0.05"/>
      </geometry>
    </collision>
    <collision>
      <origin rpy="0 0 0" xyz="0 0.05 0.1"/>
      <geometry>
        <sphere radius="0.05"/>
      </geometry>
    </collision>
  </link>
  <link name="panda_3_leftfinger">
    <visual>
      <geometry>
        <mesh filename="package://franka_description/meshes/visual/finger.dae"/>
      </geometry>
    </visual>
  </link>
  <link name="panda_3_rightfinger">
    <visual>
      <origin rpy="0 0 3.14159265359" xyz="0 0 0"/>
      <geometry>
        <mesh filename="package://franka_description/meshes/visual/finger.dae"/>
      </geometry>
    </visual>
  </link>
  <joint name="panda_3_finger_joint1" type="prismatic">
    <parent link="panda_3_hand"/>
    <child link="panda_3_leftfinger"/>
    <origin rpy="0 0 0" xyz="0 0 0.0584"/>
    <axis xyz="0 1 0"/>
    <limit effort="150" lower="0.0" upper="0.04" velocity="0.2"/>
  </joint>
  <joint name="panda_3_finger_joint2" type="prismatic">
    <parent link="panda_3_hand"/>
    <child link="panda_3_rightfinger"/>
    <origin rpy="0 0 0" xyz="0 0 0.0584"/>
    <axis xyz="0 -1 0"/>
    <limit effort="150" lower="0.0" upper="0.04" velocity="0.2"/>
    <mimic joint="panda_3_finger_joint1"/>
  </joint>
  <!-- ==================================================== -->
  <!-- UR robots -->
  <!-- ==================================================== -->
  <!--
    Base UR robot series xacro macro.

    NOTE: this is NOT a URDF. It cannot directly be loaded by consumers
    expecting a flattened '.urdf' file. See the top-level '.xacro' for that
    (but note: that .xacro must still be processed by the xacro command).

    For use in '.launch' files: use one of the 'load_urX.launch' convenience
    launch files.

    This file models the base kinematic chain of a UR robot, which then gets
    parameterised by various configuration files to convert it into a UR3(e),
    UR5(e), UR10(e) or UR16e.

    NOTE: the default kinematic parameters (ie: link lengths, frame locations,
    offets, etc) do not correspond to any particular robot. They are defaults
    only. There WILL be non-zero offsets between the Forward Kinematics results
    in TF (ie: robot_state_publisher) and the values reported by the Teach
    Pendant.

    For accurate (and robot-specific) transforms, the 'kinematics_parameters_file'
    parameter MUST point to a .yaml file containing the appropriate values for
    the targetted robot.

    If using the UniversalRobots/Universal_Robots_ROS_Driver, follow the steps
    described in the readme of that repository to extract the kinematic
    calibration from the controller and generate the required .yaml file.

    Main author of the migration to yaml configs: Ludovic Delval.

    Contributors to previous versions (in no particular order):

     - Felix Messmer
     - Kelsey Hawkins
     - Wim Meeussen
     - Shaun Edwards
     - Nadia Hammoudeh Garcia
     - Dave Hershberger
     - G. vd. Hoorn
     - Philip Long
     - Dave Coleman
     - Miguel Prada
     - Mathias Luedtke
     - Marcel Schnirring
     - Felix von Drigalski
     - Felix Exner
     - Jimmy Da Silva
     - Ajit Krisshna N L
     - Muhammad Asif Rana
  -->
  <!--
    NOTE: the macro defined in this file is NOT part of the public API of this
          package. Users CANNOT rely on this file being available, or stored in
          this location. Nor can they rely on the existence of the macro.
  -->
  <transmission name="robot3_shoulder_pan_trans">
    <type>transmission_interface/SimpleTransmission</type>
    <joint name="robot3_shoulder_pan_joint">
      <hardwareInterface>hardware_interface/PositionJointInterface</hardwareInterface>
    </joint>
    <actuator name="robot3_shoulder_pan_motor">
      <mechanicalReduction>1</mechanicalReduction>
    </actuator>
  </transmission>
  <transmission name="robot3_shoulder_lift_trans">
    <type>transmission_interface/SimpleTransmission</type>
    <joint name="robot3_shoulder_lift_joint">
      <hardwareInterface>hardware_interface/PositionJointInterface</hardwareInterface>
    </joint>
    <actuator name="robot3_shoulder_lift_motor">
      <mechanicalReduction>1</mechanicalReduction>
    </actuator>
  </transmission>
  <transmission name="robot3_elbow_trans">
    <type>transmission_interface/SimpleTransmission</type>
    <joint name="robot3_elbow_joint">
      <hardwareInterface>hardware_interface/PositionJointInterface</hardwareInterface>
    </joint>
    <actuator name="robot3_elbow_motor">
      <mechanicalReduction>1</mechanicalReduction>
    </actuator>
  </transmission>
  <transmission name="robot3_wrist_1_trans">
    <type>transmission_interface/SimpleTransmission</type>
    <joint name="robot3_wrist_1_joint">
      <hardwareInterface>hardware_interface/PositionJointInterface</hardwareInterface>
    </joint>
    <actuator name="robot3_wrist_1_motor">
      <mechanicalReduction>1</mechanicalReduction>
    </actuator>
  </transmission>
  <transmission name="robot3_wrist_2_trans">
    <type>transmission_interface/SimpleTransmission</type>
    <joint name="robot3_wrist_2_joint">
      <hardwareInterface>hardware_interface/PositionJointInterface</hardwareInterface>
    </joint>
    <actuator name="robot3_wrist_2_motor">
      <mechanicalReduction>1</mechanicalReduction>
    </actuator>
  </transmission>
  <transmission name="robot3_wrist_3_trans">
    <type>transmission_interface/SimpleTransmission</type>
    <joint name="robot3_wrist_3_joint">
      <hardwareInterface>hardware_interface/PositionJointInterface</hardwareInterface>
    </joint>
    <actuator name="robot3_wrist_3_motor">
      <mechanicalReduction>1</mechanicalReduction>
    </actuator>
  </transmission>
  <!-- links: main serial chain -->
  <link name="robot3_base_link"/>
  <link name="robot3_base_link_inertia">
    <visual>
      <origin rpy="0 0 3.14159265359" xyz="0 0 0"/>
      <geometry>
        <mesh filename="package://ur_description/meshes/ur5/visual/base.dae"/>
      </geometry>
      <material name="LightGrey">
        <color rgba="0.7 0.7 0.7 1.0"/>
      </material>
    </visual>
    <collision>
      <origin rpy="0 0 3.14159265359" xyz="0 0 0"/>
      <geometry>
        <mesh filename="package://ur_description/meshes/ur5/collision/base.stl"/>
      </geometry>
    </collision>
    <inertial>
      <mass value="4.0"/>
      <origin rpy="0 0 0" xyz="0 0 0"/>
      <inertia ixx="0.00443333156" ixy="0.0" ixz="0.0" iyy="0.00443333156" iyz="0.0" izz="0.0072"/>
    </inertial>
  </link>
  <link name="robot3_shoulder_link">
    <visual>
      <origin rpy="0 0 3.14159265359" xyz="0 0 0"/>
      <geometry>
        <mesh filename="package://ur_description/meshes/ur5/visual/shoulder.dae"/>
      </geometry>
      <material name="LightGrey">
        <color rgba="0.7 0.7 0.7 1.0"/>
      </material>
    </visual>
    <collision>
      <origin rpy="0 0 3.14159265359" xyz="0 0 0"/>
      <geometry>
        <mesh filename="package://ur_description/meshes/ur5/collision/shoulder.stl"/>
      </geometry>
    </collision>
    <inertial>
      <mass value="3.7"/>
      <origin rpy="0 0 0" xyz="0 0 0"/>
      <inertia ixx="0.0149723523444" ixy="0.0" ixz="0.0" iyy="0.0149723523444" iyz="0.0" izz="0.01040625"/>
    </inertial>
  </link>
  <link name="robot3_upper_arm_link">
    <visual>
      <origin rpy="1.57079632679 0 -1.57079632679" xyz="0 0 0.13585"/>
      <geometry>
        <mesh filename="package://ur_description/meshes/ur5/visual/upperarm.dae"/>
      </geometry>
      <material name="LightGrey">
        <color rgba="0.7 0.7 0.7 1.0"/>
      </material>
    </visual>
    <collision>
      <origin rpy="1.57079632679 0 -1.57079632679" xyz="0 0 0.13585"/>
      <geometry>
        <mesh filename="package://ur_description/meshes/ur5/collision/upperarm.stl"/>
      </geometry>
    </collision>
    <inertial>
      <mass value="8.393"/>
      <origin rpy="0 1.57079632679 0" xyz="-0.2125 0.0 0.136"/>
      <inertia ixx="0.133885781862" ixy="0.0" ixz="0.0" iyy="0.133885781862" iyz="0.0" izz="0.0151074"/>
    </inertial>
  </link>
  <link name="robot3_forearm_link">
    <visual>
      <origin rpy="1.57079632679 0 -1.57079632679" xyz="0 0 0.0165"/>
      <geometry>
        <mesh filename="package://ur_description/meshes/ur5/visual/forearm.dae"/>
      </geometry>
      <material name="LightGrey">
        <color rgba="0.7 0.7 0.7 1.0"/>
      </material>
    </visual>
    <collision>
      <origin rpy="1.57079632679 0 -1.57079632679" xyz="0 0 0.0165"/>
      <geometry>
        <mesh filename="package://ur_description/meshes/ur5/collision/forearm.stl"/>
      </geometry>
    </collision>
    <inertial>
      <mass value="2.275"/>
      <origin rpy="0 1.57079632679 0" xyz="-0.196125 0.0 0.0165"/>
      <inertia ixx="0.0312167910289" ixy="0.0" ixz="0.0" iyy="0.0312167910289" iyz="0.0" izz="0.004095"/>
    </inertial>
  </link>
  <link name="robot3_wrist_1_link">
    <visual>
      <!-- TODO: Move this to a parameter -->
      <origin rpy="1.57079632679 0 0" xyz="0 0 -0.093"/>
      <geometry>
        <mesh filename="package://ur_description/meshes/ur5/visual/wrist1.dae"/>
      </geometry>
      <material name="LightGrey">
        <color rgba="0.7 0.7 0.7 1.0"/>
      </material>
    </visual>
    <collision>
      <origin rpy="1.57079632679 0 0" xyz="0 0 -0.093"/>
      <geometry>
        <mesh filename="package://ur_description/meshes/ur5/collision/wrist1.stl"/>
      </geometry>
    </collision>
    <inertial>
      <mass value="1.219"/>
      <origin rpy="0 0 0" xyz="0 0 0"/>
      <inertia ixx="0.00201388877778" ixy="0.0" ixz="0.0" iyy="0.00201388877778" iyz="0.0" izz="0.0021942"/>
    </inertial>
  </link>
  <link name="robot3_wrist_2_link">
    <visual>
      <origin rpy="0 0 0" xyz="0 0 -0.095"/>
      <geometry>
        <mesh filename="package://ur_description/meshes/ur5/visual/wrist2.dae"/>
      </geometry>
      <material name="LightGrey">
        <color rgba="0.7 0.7 0.7 1.0"/>
      </material>
    </visual>
    <collision>
      <origin rpy="0 0 0" xyz="0 0 -0.095"/>
      <geometry>
        <mesh filename="package://ur_description/meshes/ur5/collision/wrist2.stl"/>
      </geometry>
    </collision>
    <inertial>
      <mass value="1.219"/>
      <origin rpy="0 0 0" xyz="0 0 0"/>
      <inertia ixx="0.00183103885092" ixy="0.0" ixz="0.0" iyy="0.00183103885092" iyz="0.0" izz="0.0021942"/>
    </inertial>
  </link>
  <link name="robot3_wrist_3_link">
    <visual>
      <origin rpy="1.57079632679 0 0" xyz="0 0 -0.0818"/>
      <geometry>
        <mesh filename="package://ur_description/meshes/ur5/visual/wrist3.dae"/>
      </geometry>
      <material name="LightGrey">
        <color rgba="0.7 0.7 0.7 1.0"/>
      </material>
    </visual>
    <collision>
      <origin rpy="1.57079632679 0 0" xyz="0 0 -0.0818"/>
      <geometry>
        <mesh filename="package://ur_description/meshes/ur5/collision/wrist3.stl"/>
      </geometry>
    </collision>
    <inertial>
      <mass value="0.1879"/>
      <origin rpy="0 0 0" xyz="0.0 0.0 -0.01525"/>
      <inertia ixx="8.06247260834e-05" ixy="0.0" ixz="0.0" iyy="8.06247260834e-05" iyz="0.0" izz="0.0001321171875"/>
    </inertial>
  </link>
  <!-- joints: main serial chain -->
  <joint name="robot3_base_link-base_link_inertia" type="fixed">
    <parent link="robot3_base_link"/>
    <child link="robot3_base_link_inertia"/>
    <!-- 'base_link' is REP-103 aligned (so X+ forward), while the internal
           frames of the robot/controller have X+ pointing backwards.
           Use the joint between 'base_link' and 'base_link_inertia' (a dummy
           link/frame) to introduce the necessary rotation over Z (of pi rad).
      -->
    <origin rpy="0 0 3.14159265359" xyz="0 0 0"/>
  </joint>
  <joint name="robot3_shoulder_pan_joint" type="revolute">
    <parent link="robot3_base_link_inertia"/>
    <child link="robot3_shoulder_link"/>
    <origin rpy="0 0 0" xyz="0 0 0.089159"/>
    <axis xyz="0 0 1"/>
    <limit effort="150.0" lower="-6.28318530718" upper="6.28318530718" velocity="3.14159265359"/>
    <dynamics damping="0" friction="0"/>
  </joint>
  <joint name="robot3_shoulder_lift_joint" type="revolute">
    <parent link="robot3_shoulder_link"/>
    <child link="robot3_upper_arm_link"/>
    <origin rpy="1.570796327 0 0" xyz="0 0 0"/>
    <axis xyz="0 0 1"/>
    <limit effort="150.0" lower="-6.28318530718" upper="6.28318530718" velocity="3.14159265359"/>
    <dynamics damping="0" friction="0"/>
  </joint>
  <joint name="robot3_elbow_joint" type="revolute">
    <parent link="robot3_upper_arm_link"/>
    <child link="robot3_forearm_link"/>
    <origin rpy="0 0 0" xyz="-0.425 0 0"/>
    <axis xyz="0 0 1"/>
    <limit effort="150.0" lower="-3.14159265359" upper="3.14159265359" velocity="3.14159265359"/>
    <dynamics damping="0" friction="0"/>
  </joint>
  <joint name="robot3_wrist_1_joint" type="revolute">
    <parent link="robot3_forearm_link"/>
    <child link="robot3_wrist_1_link"/>
    <origin rpy="0 0 0" xyz="-0.39225 0 0.10915"/>
    <axis xyz="0 0 1"/>
    <limit effort="28.0" lower="-6.28318530718" upper="6.28318530718" velocity="3.14159265359"/>
    <dynamics damping="0" friction="0"/>
  </joint>
  <joint name="robot3_wrist_2_joint" type="revolute">
    <parent link="robot3_wrist_1_link"/>
    <child link="robot3_wrist_2_link"/>
    <origin rpy="1.570796327 0 0" xyz="0 -0.09465 -1.9413039509e-11"/>
    <axis xyz="0 0 1"/>
    <limit effort="28.0" lower="-6.28318530718" upper="6.28318530718" velocity="3.14159265359"/>
    <dynamics damping="0" friction="0"/>
  </joint>
  <joint name="robot3_wrist_3_joint" type="revolute">
    <parent link="robot3_wrist_2_link"/>
    <child link="robot3_wrist_3_link"/>
    <origin rpy="1.57079632659 3.14159265359 3.14159265359" xyz="0 0.0823 -1.68800121668e-11"/>
    <axis xyz="0 0 1"/>
    <limit effort="28.0" lower="-6.28318530718" upper="6.28318530718" velocity="3.14159265359"/>
    <dynamics damping="0" friction="0"/>
  </joint>
  <!-- ROS-Industrial 'base' frame: base_link to UR 'Base' Coordinates transform -->
  <link name="robot3_base"/>
  <joint name="robot3_base_link-base_fixed_joint" type="fixed">
    <!-- Note the rotation over Z of pi radians: as base_link is REP-103
           aligned (ie: has X+ forward, Y+ left and Z+ up), this is needed
           to correctly align 'base' with the 'Base' coordinate system of
           the UR controller.
      -->
    <origin rpy="0 0 3.14159265359" xyz="0 0 0"/>
    <parent link="robot3_base_link"/>
    <child link="robot3_base"/>
  </joint>
  <!-- ROS-Industrial 'flange' frame: attachment point for EEF models -->
  <link name="robot3_flange"/>
  <joint name="robot3_wrist_3-flange" type="fixed">
    <parent link="robot3_wrist_3_link"/>
    <child link="robot3_flange"/>
    <origin rpy="0 -1.57079632679 -1.57079632679" xyz="0 0 0"/>
  </joint>
  <!-- ROS-Industrial 'tool0' frame: all-zeros tool frame -->
  <link name="robot3_tool0"/>
  <joint name="robot3_flange-tool0" type="fixed">
    <!-- default toolframe: X+ left, Y+ up, Z+ front -->
    <origin rpy="1.57079632679 0 1.57079632679" xyz="0 0 0"/>
    <parent link="robot3_flange"/>
    <child link="robot3_tool0"/>
  </joint>
  <joint name="robot3-robot3_pedestal_joint" type="fixed">
    <parent link="robot3_pedestal_link"/>
    <child link="robot3_base_link"/>
    <origin rpy="0 0 -0.785398163397" xyz="0 0 0.95"/>
  </joint>
  <!-- ==================================================== -->
  <!-- Robot 1,2 pedestal -->
  <!-- ==================================================== -->
  <joint name="robot1_pedestal_joint" type="fixed">
    <origin rpy="0 0 0" xyz="-3.6 11.6 0.0"/>
    <parent link="world_interface"/>
    <child link="robot1_pedestal_link"/>
  </joint>
  <link name="robot1_pedestal_link">
    <visual>
      <origin xyz="0 0 0.475"/>
      <geometry>
        <box size="0.3 0.3 0.95"/>
      </geometry>
      <material name="pedestal_color">
        <color rgba="0 0.156862745098 0.525490196078 1"/>
      </material>
    </visual>
    <collision>
      <origin xyz="0 0 0.475"/>
      <geometry>
        <box size="0.3 0.3 0.95"/>
      </geometry>
    </collision>
    <inertial>
      <mass value="500"/>
      <origin rpy="0 0 0" xyz="0 0 0"/>
      <inertia ixx="0.001" ixy="0" ixz="0" iyy="0.001" iyz="0" izz="0.001"/>
    </inertial>
  </link>
  <gazebo reference="robot1_pedestal_link">
    <material>Gazebo/Blue</material>
  </gazebo>
  <joint name="robot2_pedestal_joint" type="fixed">
    <origin rpy="0 0 0" xyz="-3.6 7.6 0.0"/>
    <parent link="world_interface"/>
    <child link="robot2_pedestal_link"/>
  </joint>
  <link name="robot2_pedestal_link">
    <visual>
      <origin xyz="0 0 0.475"/>
      <geometry>
        <box size="0.3 0.3 0.95"/>
      </geometry>
      <material name="pedestal_color">
        <color rgba="0 0.156862745098 0.525490196078 1"/>
      </material>
    </visual>
    <collision>
      <origin xyz="0 0 0.475"/>
      <geometry>
        <box size="0.3 0.3 0.95"/>
      </geometry>
    </collision>
    <inertial>
      <mass value="500"/>
      <origin rpy="0 0 0" xyz="0 0 0"/>
      <inertia ixx="0.001" ixy="0" ixz="0" iyy="0.001" iyz="0" izz="0.001"/>
    </inertial>
  </link>
  <gazebo reference="robot2_pedestal_link">
    <material>Gazebo/Blue</material>
  </gazebo>
  <joint name="robot3_pedestal_joint" type="fixed">
    <origin rpy="0 0 0" xyz="-1.5 8 0.0"/>
    <parent link="world_interface"/>
    <child link="robot3_pedestal_link"/>
  </joint>
  <link name="robot3_pedestal_link">
    <visual>
      <origin xyz="0 0 0.475"/>
      <geometry>
        <box size="0.3 0.3 0.95"/>
      </geometry>
      <material name="pedestal_color">
        <color rgba="0 0.156862745098 0.525490196078 1"/>
      </material>
    </visual>
    <collision>
      <origin xyz="0 0 0.475"/>
      <geometry>
        <box size="0.3 0.3 0.95"/>
      </geometry>
    </collision>
    <inertial>
      <mass value="500"/>
      <origin rpy="0 0 0" xyz="0 0 0"/>
      <inertia ixx="0.001" ixy="0" ixz="0" iyy="0.001" iyz="0" izz="0.001"/>
    </inertial>
  </link>
  <gazebo reference="robot3_pedestal_link">
    <material>Gazebo/Blue</material>
  </gazebo>
  <!-- link list -->
  <link name="bin_1_base_link">
    <visual>
      <origin rpy="0 0 0" xyz="0 0 0"/>
      <geometry>
        <mesh filename="package://omtp_support/meshes/bin/visual/bin.dae"/>
        <scale>0.6 0.6 0.6</scale>
      </geometry>
    </visual>
    <collision>
      <origin rpy="0 0 0" xyz="0 0 0"/>
      <geometry>
        <mesh filename="package://omtp_support/meshes/bin/collision/bin_bottom.dae"/>
        <scale>0.6 0.6 0.6</scale>
      </geometry>
    </collision>
    <collision>
      <origin rpy="0 0 0" xyz="0 0 0"/>
      <geometry>
        <mesh filename="package://omtp_support/meshes/bin/collision/bin_sides.dae"/>
        <scale>0.6 0.6 0.6</scale>
      </geometry>
    </collision>
    <inertial>
      <origin rpy="0 0 0" xyz="0 0 0"/>
      <inertia ixx="1.0" ixy="0" ixz="0" iyy="1.0" iyz="0" izz="1.0"/>
      <mass value="100"/>
    </inertial>
  </link>
  <link name="bin_1_drop_point">
    <inertial>
      <origin rpy="0 0 0" xyz="0 0 0"/>
      <inertia ixx="1.0" ixy="0" ixz="0" iyy="1.0" iyz="0" izz="1.0"/>
      <mass value="1.0"/>
    </inertial>
  </link>
  <!-- joint list -->
  <joint name="bin_1_joint_1" type="fixed">
    <origin rpy="0 0 0" xyz="0 0 1.0"/>
    <parent link="bin_1_base_link"/>
    <child link="bin_1_drop_point"/>
  </joint>
  <!-- link list -->
  <link name="bin_2_base_link">
    <visual>
      <origin rpy="0 0 0" xyz="0 0 0"/>
      <geometry>
        <mesh filename="package://omtp_support/meshes/bin/visual/bin.dae"/>
        <scale>0.6 0.6 0.6</scale>
      </geometry>
    </visual>
    <collision>
      <origin rpy="0 0 0" xyz="0 0 0"/>
      <geometry>
        <mesh filename="package://omtp_support/meshes/bin/collision/bin_bottom.dae"/>
        <scale>0.6 0.6 0.6</scale>
      </geometry>
    </collision>
    <collision>
      <origin rpy="0 0 0" xyz="0 0 0"/>
      <geometry>
        <mesh filename="package://omtp_support/meshes/bin/collision/bin_sides.dae"/>
        <scale>0.6 0.6 0.6</scale>
      </geometry>
    </collision>
    <inertial>
      <origin rpy="0 0 0" xyz="0 0 0"/>
      <inertia ixx="1.0" ixy="0" ixz="0" iyy="1.0" iyz="0" izz="1.0"/>
      <mass value="100"/>
    </inertial>
  </link>
  <link name="bin_2_drop_point">
    <inertial>
      <origin rpy="0 0 0" xyz="0 0 0"/>
      <inertia ixx="1.0" ixy="0" ixz="0" iyy="1.0" iyz="0" izz="1.0"/>
      <mass value="1.0"/>
    </inertial>
  </link>
  <!-- joint list -->
  <joint name="bin_2_joint_1" type="fixed">
    <origin rpy="0 0 0" xyz="0 0 1.0"/>
    <parent link="bin_2_base_link"/>
    <child link="bin_2_drop_point"/>
  </joint>
  <!-- link list -->
  <link name="bin_3_base_link">
    <visual>
      <origin rpy="0 0 0" xyz="0 0 0"/>
      <geometry>
        <mesh filename="package://omtp_support/meshes/bin/visual/bin.dae"/>
        <scale>0.6 0.6 0.6</scale>
      </geometry>
    </visual>
    <collision>
      <origin rpy="0 0 0" xyz="0 0 0"/>
      <geometry>
        <mesh filename="package://omtp_support/meshes/bin/collision/bin_bottom.dae"/>
        <scale>0.6 0.6 0.6</scale>
      </geometry>
    </collision>
    <collision>
      <origin rpy="0 0 0" xyz="0 0 0"/>
      <geometry>
        <mesh filename="package://omtp_support/meshes/bin/collision/bin_sides.dae"/>
        <scale>0.6 0.6 0.6</scale>
      </geometry>
    </collision>
    <inertial>
      <origin rpy="0 0 0" xyz="0 0 0"/>
      <inertia ixx="1.0" ixy="0" ixz="0" iyy="1.0" iyz="0" izz="1.0"/>
      <mass value="100"/>
    </inertial>
  </link>
  <link name="bin_3_drop_point">
    <inertial>
      <origin rpy="0 0 0" xyz="0 0 0"/>
      <inertia ixx="1.0" ixy="0" ixz="0" iyy="1.0" iyz="0" izz="1.0"/>
      <mass value="1.0"/>
    </inertial>
  </link>
  <!-- joint list -->
  <joint name="bin_3_joint_1" type="fixed">
    <origin rpy="0 0 0" xyz="0 0 1.0"/>
    <parent link="bin_3_base_link"/>
    <child link="bin_3_drop_point"/>
  </joint>
  <!-- link list -->
  <link name="bin_4_base_link">
    <visual>
      <origin rpy="0 0 0" xyz="0 0 0"/>
      <geometry>
        <mesh filename="package://omtp_support/meshes/bin/visual/bin.dae"/>
        <scale>0.6 0.6 0.6</scale>
      </geometry>
    </visual>
    <collision>
      <origin rpy="0 0 0" xyz="0 0 0"/>
      <geometry>
        <mesh filename="package://omtp_support/meshes/bin/collision/bin_bottom.dae"/>
        <scale>0.6 0.6 0.6</scale>
      </geometry>
    </collision>
    <collision>
      <origin rpy="0 0 0" xyz="0 0 0"/>
      <geometry>
        <mesh filename="package://omtp_support/meshes/bin/collision/bin_sides.dae"/>
        <scale>0.6 0.6 0.6</scale>
      </geometry>
    </collision>
    <inertial>
      <origin rpy="0 0 0" xyz="0 0 0"/>
      <inertia ixx="1.0" ixy="0" ixz="0" iyy="1.0" iyz="0" izz="1.0"/>
      <mass value="100"/>
    </inertial>
  </link>
  <link name="bin_4_drop_point">
    <inertial>
      <origin rpy="0 0 0" xyz="0 0 0"/>
      <inertia ixx="1.0" ixy="0" ixz="0" iyy="1.0" iyz="0" izz="1.0"/>
      <mass value="1.0"/>
    </inertial>
  </link>
  <!-- joint list -->
  <joint name="bin_4_joint_1" type="fixed">
    <origin rpy="0 0 0" xyz="0 0 1.0"/>
    <parent link="bin_4_base_link"/>
    <child link="bin_4_drop_point"/>
  </joint>
  <!-- link list -->
  <link name="bin_5_base_link">
    <visual>
      <origin rpy="0 0 0" xyz="0 0 0"/>
      <geometry>
        <mesh filename="package://omtp_support/meshes/bin/visual/bin.dae"/>
        <scale>0.6 0.6 0.6</scale>
      </geometry>
    </visual>
    <collision>
      <origin rpy="0 0 0" xyz="0 0 0"/>
      <geometry>
        <mesh filename="package://omtp_support/meshes/bin/collision/bin_bottom.dae"/>
        <scale>0.6 0.6 0.6</scale>
      </geometry>
    </collision>
    <collision>
      <origin rpy="0 0 0" xyz="0 0 0"/>
      <geometry>
        <mesh filename="package://omtp_support/meshes/bin/collision/bin_sides.dae"/>
        <scale>0.6 0.6 0.6</scale>
      </geometry>
    </collision>
    <inertial>
      <origin rpy="0 0 0" xyz="0 0 0"/>
      <inertia ixx="1.0" ixy="0" ixz="0" iyy="1.0" iyz="0" izz="1.0"/>
      <mass value="100"/>
    </inertial>
  </link>
  <link name="bin_5_drop_point">
    <inertial>
      <origin rpy="0 0 0" xyz="0 0 0"/>
      <inertia ixx="1.0" ixy="0" ixz="0" iyy="1.0" iyz="0" izz="1.0"/>
      <mass value="1.0"/>
    </inertial>
  </link>
  <!-- joint list -->
  <joint name="bin_5_joint_1" type="fixed">
    <origin rpy="0 0 0" xyz="0 0 1.0"/>
    <parent link="bin_5_base_link"/>
    <child link="bin_5_drop_point"/>
  </joint>
  <!-- Bin 1 -->
  <joint name="bin_1_joint" type="fixed">
    <parent link="world_interface"/>
    <child link="bin_1_base_link"/>
    <origin rpy="0 0 0" xyz="-2 12 0.0"/>
  </joint>
  <!-- Bin 2 -->
  <joint name="bin_2_joint" type="fixed">
    <parent link="world_interface"/>
    <child link="bin_2_base_link"/>
    <origin rpy="0 0 0" xyz="-4.25 10.3 0.0"/>
  </joint>
  <!-- Bin 3 -->
  <joint name="bin_3_joint" type="fixed">
    <parent link="world_interface"/>
    <child link="bin_3_base_link"/>
    <origin rpy="0 0 0" xyz="-4.2 9.0 0.0"/>
  </joint>
  <!-- Bin 4 -->
  <joint name="bin_4_joint" type="fixed">
    <parent link="world_interface"/>
    <child link="bin_4_base_link"/>
    <origin rpy="0 0 0" xyz="-0.7 7.0 0.0"/>
  </joint>
  <!-- Bin 5 -->
  <joint name="bin_5_joint" type="fixed">
    <parent link="world_interface"/>
    <child link="bin_5_base_link"/>
    <origin rpy="0 0 -1.57079632679" xyz="-4.0 7.0 0.0"/>
  </joint>
  <!-- ==================================================== -->
  <!-- Festo Modules -->
  <!-- ==================================================== -->
  <!-- Links -->
  <link name="festo_bypass_1festo_module">
    <visual>
      <geometry>
        <mesh filename="package://aau_lab_ros_models/meshes/festo_bypass_module/festo_bypass_module.dae"/>
      </geometry>
    </visual>
    <collision>
      <geometry>
        <mesh filename="package://aau_lab_ros_models/meshes/festo_bypass_module/festo_bypass_module.dae"/>
      </geometry>
    </collision>
    <inertial>
      <inertia ixx="1.0" ixy="0" ixz="0" iyy="1.0" iyz="0" izz="1.0"/>
      <mass value="100"/>
    </inertial>
  </link>
  <joint name="festo_bypass_1festo_module_to_world_interface" type="fixed">
    <origin rpy="0 0 0" xyz="-3.0 11.45 0.0"/>
    <parent link="world_interface"/>
    <child link="festo_bypass_1festo_module"/>
    <!-- <origin xyz="0 0 0" rpy="0 0 0" /> -->
  </joint>
  <!-- Links -->
  <link name="festo_robot_1festo_module">
    <visual>
      <geometry>
        <mesh filename="package://aau_lab_ros_models/meshes/festo_robot_module/festo_robot_module.dae"/>
      </geometry>
    </visual>
    <collision>
      <geometry>
        <mesh filename="package://aau_lab_ros_models/meshes/festo_robot_module/festo_robot_module.dae"/>
      </geometry>
    </collision>
    <inertial>
      <inertia ixx="1.0" ixy="0" ixz="0" iyy="1.0" iyz="0" izz="1.0"/>
      <mass value="100"/>
    </inertial>
  </link>
  <joint name="festo_robot_1festo_module_to_world_interface" type="fixed">
    <origin rpy="0 0 0" xyz="-3.0 10.3 0.0"/>
    <parent link="world_interface"/>
    <child link="festo_robot_1festo_module"/>
    <!-- <origin xyz="0 0 0" rpy="0 0 0" /> -->
  </joint>
  <!-- Links -->
  <link name="festo_straight_2festo_module">
    <visual>
      <geometry>
        <mesh filename="package://aau_lab_ros_models/meshes/festo_straight_module/festo_straight_module.dae"/>
      </geometry>
    </visual>
    <collision>
      <geometry>
        <mesh filename="package://aau_lab_ros_models/meshes/festo_straight_module/festo_straight_module.dae"/>
      </geometry>
    </collision>
    <inertial>
      <inertia ixx="1.0" ixy="0" ixz="0" iyy="1.0" iyz="0" izz="1.0"/>
      <mass value="100"/>
    </inertial>
  </link>
  <joint name="festo_straight_2festo_module_to_world_interface" type="fixed">
    <origin rpy="0 0 0" xyz="-3.0 8.0 0.0"/>
    <parent link="world_interface"/>
    <child link="festo_straight_2festo_module"/>
    <!-- <origin xyz="0 0 0" rpy="0 0 0" /> -->
  </joint>
  <!-- Links -->
  <link name="festo_straight_3festo_module">
    <visual>
      <geometry>
        <mesh filename="package://aau_lab_ros_models/meshes/festo_straight_module/festo_straight_module.dae"/>
      </geometry>
    </visual>
    <collision>
      <geometry>
        <mesh filename="package://aau_lab_ros_models/meshes/festo_straight_module/festo_straight_module.dae"/>
      </geometry>
    </collision>
    <inertial>
      <inertia ixx="1.0" ixy="0" ixz="0" iyy="1.0" iyz="0" izz="1.0"/>
      <mass value="100"/>
    </inertial>
  </link>
  <joint name="festo_straight_3festo_module_to_world_interface" type="fixed">
    <origin rpy="0 0 0" xyz="-3.0 9.15 0.0"/>
    <parent link="world_interface"/>
    <child link="festo_straight_3festo_module"/>
    <!-- <origin xyz="0 0 0" rpy="0 0 0" /> -->
  </joint>
  <!-- Links -->
  <link name="festo_straight_4festo_module">
    <visual>
      <geometry>
        <mesh filename="package://aau_lab_ros_models/meshes/festo_straight_module/festo_straight_module.dae"/>
      </geometry>
    </visual>
    <collision>
      <geometry>
        <mesh filename="package://aau_lab_ros_models/meshes/festo_straight_module/festo_straight_module.dae"/>
      </geometry>
    </collision>
    <inertial>
      <inertia ixx="1.0" ixy="0" ixz="0" iyy="1.0" iyz="0" izz="1.0"/>
      <mass value="100"/>
    </inertial>
  </link>
  <joint name="festo_straight_4festo_module_to_world_interface" type="fixed">
    <origin rpy="0 0 0" xyz="-3.0 10.30 0.0"/>
    <parent link="world_interface"/>
    <child link="festo_straight_4festo_module"/>
    <!-- <origin xyz="0 0 0" rpy="0 0 0" /> -->
  </joint>
  <!-- Links -->
  <link name="festo_t_1festo_module">
    <visual>
      <geometry>
        <mesh filename="package://aau_lab_ros_models/meshes/festo_t_module/festo_t_module.dae"/>
      </geometry>
    </visual>
    <collision>
      <geometry>
        <mesh filename="package://aau_lab_ros_models/meshes/festo_t_module/festo_t_module.dae"/>
      </geometry>
    </collision>
    <inertial>
      <inertia ixx="1.0" ixy="0" ixz="0" iyy="1.0" iyz="0" izz="1.0"/>
      <mass value="100"/>
    </inertial>
  </link>
  <joint name="festo_t_1festo_module_to_world_interface" type="fixed">
    <origin rpy="0 0 -1.57079632679" xyz="-3.0 7.0 0.0"/>
    <parent link="world_interface"/>
    <child link="festo_t_1festo_module"/>
    <!-- <origin xyz="0 0 0" rpy="0 0 0" /> -->
  </joint>
  <!-- Links -->
  <link name="festo_straight_1festo_module">
    <visual>
      <geometry>
        <mesh filename="package://aau_lab_ros_models/meshes/festo_straight_module/festo_straight_module.dae"/>
      </geometry>
    </visual>
    <collision>
      <geometry>
        <mesh filename="package://aau_lab_ros_models/meshes/festo_straight_module/festo_straight_module.dae"/>
      </geometry>
    </collision>
    <inertial>
      <inertia ixx="1.0" ixy="0" ixz="0" iyy="1.0" iyz="0" izz="1.0"/>
      <mass value="100"/>
    </inertial>
  </link>
  <joint name="festo_straight_1festo_module_to_world_interface" type="fixed">
    <origin rpy="0 0 -1.57079632679" xyz="-1.84 7.0 0.0"/>
    <parent link="world_interface"/>
    <child link="festo_straight_1festo_module"/>
    <!-- <origin xyz="0 0 0" rpy="0 0 0" /> -->
  </joint>
</robot>

