<?xml version="1.0" encoding="utf-8"?>
<!-- =================================================================================== -->
<!-- |    This document was autogenerated by xacro from omtp_factory.xacro             | -->
<!-- |    EDITING THIS FILE BY HAND IS NOT RECOMMENDED                                 | -->
<!-- =================================================================================== -->
<robot name="omtp">
  <!-- ==================================================== -->
  <!-- INITIAL SETUP OF WORLD LINK AND WORLD_INTERFACE LINK -->
  <!-- ==================================================== -->
  <!-- world -->
  <link name="world"/>
  <!-- world_interface. Makes it convenient to move the whole environment according to the world origin -->
  <link name="world_interface"/>
  <!-- world<->world_interface joint -->
  <joint name="world_interface_to_world" type="fixed">
    <parent link="world"/>
    <child link="world_interface"/>
  </joint>
  <!-- Links -->
  <link name="fib14">
    <visual>
      <geometry>
        <mesh filename="package://aau_lab_ros_models/meshes/fib14/fib14.dae"/>
      </geometry>
    </visual>
    <collision>
      <geometry>
        <mesh filename="package://aau_lab_ros_models/meshes/fib14/fib14.dae"/>
      </geometry>
    </collision>
    <inertial>
      <inertia ixx="1.0" ixy="0" ixz="0" iyy="1.0" iyz="0" izz="1.0"/>
      <mass value="100"/>
    </inertial>
  </link>
  <joint name="fib14_to_world_interface" type="fixed">
    <parent link="world_interface"/>
    <child link="fib14"/>
    <origin rpy="0 0 0" xyz="0 0 0"/>
  </joint>
  <joint name="panda_1_virtual_joint" type="fixed">
    <parent link="robot1_pedestal_link"/>
    <child link="panda_1_link0"/>
    <origin rpy="0 0 0" xyz="0 0 0.95"/>
    <dynamics damping="1.0"/>
  </joint>
  <link name="panda_1_link0">
    <visual>
      <geometry>
        <mesh filename="package://franka_description/meshes/visual/link0.dae"/>
      </geometry>
    </visual>
    <collision>
      <geometry>
        <mesh filename="package://franka_description/meshes/collision/link0.stl"/>
      </geometry>
    </collision>
    <inertial>
      <origin rpy="0 0 0" xyz="0 0 0"/>
      <mass value="3.06"/>
      <inertia ixx="0.3" ixy="0.0" ixz="0.0" iyy="0.3" iyz="0.0" izz="0.3"/>
    </inertial>
  </link>
  <link name="panda_1_link1">
    <visual>
      <geometry>
        <mesh filename="package://franka_description/meshes/visual/link1.dae"/>
      </geometry>
    </visual>
    <collision>
      <geometry>
        <mesh filename="package://franka_description/meshes/collision/link1.stl"/>
      </geometry>
    </collision>
    <inertial>
      <origin rpy="0 0 0" xyz="0 0 0"/>
      <mass value="2.34"/>
      <inertia ixx="0.3" ixy="0.0" ixz="0.0" iyy="0.3" iyz="0.0" izz="0.3"/>
    </inertial>
  </link>
  <link name="panda_1_link2">
    <visual>
      <geometry>
        <mesh filename="package://franka_description/meshes/visual/link2.dae"/>
      </geometry>
    </visual>
    <collision>
      <geometry>
        <mesh filename="package://franka_description/meshes/collision/link2.stl"/>
      </geometry>
    </collision>
    <inertial>
      <origin rpy="0 0 0" xyz="0 0 0"/>
      <mass value="2.36"/>
      <inertia ixx="0.3" ixy="0.0" ixz="0.0" iyy="0.3" iyz="0.0" izz="0.3"/>
    </inertial>
  </link>
  <link name="panda_1_link3">
    <visual>
      <geometry>
        <mesh filename="package://franka_description/meshes/visual/link3.dae"/>
      </geometry>
    </visual>
    <collision>
      <geometry>
        <mesh filename="package://franka_description/meshes/collision/link3.stl"/>
      </geometry>
    </collision>
    <inertial>
      <origin rpy="0 0 0" xyz="0 0 0"/>
      <mass value="2.38"/>
      <inertia ixx="0.3" ixy="0.0" ixz="0.0" iyy="0.3" iyz="0.0" izz="0.3"/>
    </inertial>
  </link>
  <link name="panda_1_link4">
    <visual>
      <geometry>
        <mesh filename="package://franka_description/meshes/visual/link4.dae"/>
      </geometry>
    </visual>
    <collision>
      <geometry>
        <mesh filename="package://franka_description/meshes/collision/link4.stl"/>
      </geometry>
    </collision>
    <inertial>
      <origin rpy="0 0 0" xyz="0 0 0"/>
      <mass value="2.43"/>
      <inertia ixx="0.3" ixy="0.0" ixz="0.0" iyy="0.3" iyz="0.0" izz="0.3"/>
    </inertial>
  </link>
  <link name="panda_1_link5">
    <visual>
      <geometry>
        <mesh filename="package://franka_description/meshes/visual/link5.dae"/>
      </geometry>
    </visual>
    <collision>
      <geometry>
        <mesh filename="package://franka_description/meshes/collision/link5.stl"/>
      </geometry>
    </collision>
    <inertial>
      <origin rpy="0 0 0" xyz="0 0 0"/>
      <mass value="3.5"/>
      <inertia ixx="0.3" ixy="0.0" ixz="0.0" iyy="0.3" iyz="0.0" izz="0.3"/>
    </inertial>
  </link>
  <link name="panda_1_link6">
    <visual>
      <geometry>
        <mesh filename="package://franka_description/meshes/visual/link6.dae"/>
      </geometry>
    </visual>
    <collision>
      <geometry>
        <mesh filename="package://franka_description/meshes/collision/link6.stl"/>
      </geometry>
    </collision>
    <inertial>
      <origin rpy="0 0 0" xyz="0 0 0"/>
      <mass value="1.47"/>
      <inertia ixx="0.3" ixy="0.0" ixz="0.0" iyy="0.3" iyz="0.0" izz="0.3"/>
    </inertial>
  </link>
  <link name="panda_1_link7">
    <visual>
      <geometry>
        <mesh filename="package://franka_description/meshes/visual/link7.dae"/>
      </geometry>
    </visual>
    <collision>
      <geometry>
        <mesh filename="package://franka_description/meshes/collision/link7.stl"/>
      </geometry>
    </collision>
    <inertial>
      <origin rpy="0 0 0" xyz="0 0 0"/>
      <mass value="0.45"/>
      <inertia ixx="0.3" ixy="0.0" ixz="0.0" iyy="0.3" iyz="0.0" izz="0.3"/>
    </inertial>
  </link>
  <link name="panda_1_link8">
    <inertial>
      <origin rpy="0 0 0" xyz="0 0 0"/>
      <mass value="0.0"/>
      <inertia ixx="0.3" ixy="0.0" ixz="0.0" iyy="0.3" iyz="0.0" izz="0.3"/>
    </inertial>
  </link>
  <joint name="panda_1_joint1" type="revolute">
    <safety_controller k_position="100.0" k_velocity="40.0" soft_lower_limit="-2.8973" soft_upper_limit="2.8973"/>
    <origin rpy="0 0 0" xyz="0 0 0.333"/>
    <parent link="panda_1_link0"/>
    <child link="panda_1_link1"/>
    <limit effort="87" lower="-2.8973" upper="2.8973" velocity="2.175"/>
    <axis xyz="0 0 1"/>
    <dynamics damping="1.0"/>
  </joint>
  <joint name="panda_1_joint2" type="revolute">
    <safety_controller k_position="100.0" k_velocity="40.0" soft_lower_limit="-1.7628" soft_upper_limit="1.7628"/>
    <origin rpy="-1.57079632679 0 0" xyz="0 0 0"/>
    <parent link="panda_1_link1"/>
    <child link="panda_1_link2"/>
    <limit effort="87" lower="-1.7628" upper="1.7628" velocity="2.175"/>
    <axis xyz="0 0 1"/>
    <dynamics damping="1.0"/>
  </joint>
  <joint name="panda_1_joint3" type="revolute">
    <safety_controller k_position="100.0" k_velocity="40.0" soft_lower_limit="-2.8973" soft_upper_limit="2.8973"/>
    <origin rpy="1.57079632679 0 0" xyz="0 -0.316 0"/>
    <parent link="panda_1_link2"/>
    <child link="panda_1_link3"/>
    <limit effort="87" lower="-2.8973" upper="2.8973" velocity="2.175"/>
    <axis xyz="0 0 1"/>
    <dynamics damping="1.0"/>
  </joint>
  <joint name="panda_1_joint4" type="revolute">
    <safety_controller k_position="100.0" k_velocity="40.0" soft_lower_limit="-3.0718" soft_upper_limit="-0.0698"/>
    <origin rpy="1.57079632679 0 0" xyz="0.0825 0 0"/>
    <parent link="panda_1_link3"/>
    <child link="panda_1_link4"/>
    <limit effort="87" lower="-3.0718" upper="-0.0698" velocity="2.175"/>
    <axis xyz="0 0 1"/>
    <dynamics damping="1.0"/>
  </joint>
  <joint name="panda_1_joint5" type="revolute">
    <safety_controller k_position="100.0" k_velocity="40.0" soft_lower_limit="-2.8973" soft_upper_limit="2.8973"/>
    <origin rpy="-1.57079632679 0 0" xyz="-0.0825 0.384 0"/>
    <parent link="panda_1_link4"/>
    <child link="panda_1_link5"/>
    <limit effort="12" lower="-2.8973" upper="2.8973" velocity="2.61"/>
    <axis xyz="0 0 1"/>
    <dynamics damping="1.0"/>
  </joint>
  <joint name="panda_1_joint6" type="revolute">
    <safety_controller k_position="100.0" k_velocity="40.0" soft_lower_limit="-0.0175" soft_upper_limit="3.7525"/>
    <origin rpy="1.57079632679 0 0" xyz="0 0 0"/>
    <parent link="panda_1_link5"/>
    <child link="panda_1_link6"/>
    <limit effort="12" lower="-0.0175" upper="3.7525" velocity="2.61"/>
    <axis xyz="0 0 1"/>
    <dynamics damping="1.0"/>
  </joint>
  <joint name="panda_1_joint7" type="revolute">
    <safety_controller k_position="100.0" k_velocity="40.0" soft_lower_limit="-2.8973" soft_upper_limit="2.8973"/>
    <origin rpy="1.57079632679 0 0" xyz="0.088 0 0"/>
    <parent link="panda_1_link6"/>
    <child link="panda_1_link7"/>
    <limit effort="12" lower="-2.8973" upper="2.8973" velocity="2.61"/>
    <axis xyz="0 0 1"/>
    <dynamics damping="1.0"/>
  </joint>
  <joint name="panda_1_joint8" type="fixed">
    <origin rpy="0 0 0" xyz="0 0 0.107"/>
    <parent link="panda_1_link7"/>
    <child link="panda_1_link8"/>
    <axis xyz="0 0 0"/>
    <dynamics damping="1.0"/>
  </joint>
  <joint name="panda_1_hand_joint" type="fixed">
    <parent link="panda_1_link8"/>
    <child link="panda_1_hand"/>
    <origin rpy="0 0 -0.785398163397" xyz="0 0 0"/>
  </joint>
  <link name="panda_1_hand">
    <visual>
      <geometry>
        <mesh filename="package://franka_description/meshes/visual/hand.dae"/>
      </geometry>
    </visual>
    <collision>
      <geometry>
        <mesh filename="package://franka_description/meshes/collision/hand.stl"/>
      </geometry>
    </collision>
    <inertial>
      <origin rpy="0 0 0" xyz="0 0 0"/>
      <mass value="0.48"/>
      <inertia ixx="0.1" ixy="0.0" ixz="0.0" iyy="0.1" iyz="0.0" izz="0.1"/>
    </inertial>
  </link>
  <link name="panda_1_leftfinger">
    <visual>
      <geometry>
        <mesh filename="package://franka_description/meshes/visual/finger.dae"/>
      </geometry>
    </visual>
    <collision>
      <geometry>
        <mesh filename="package://franka_description/meshes/collision/finger.stl"/>
      </geometry>
    </collision>
    <inertial>
      <origin rpy="0 0 0" xyz="0 0 0"/>
      <mass value="0.1"/>
      <inertia ixx="0.1" ixy="0.0" ixz="0.0" iyy="0.1" iyz="0.0" izz="0.1"/>
    </inertial>
  </link>
  <link name="panda_1_rightfinger">
    <visual>
      <origin rpy="0 0 3.14159265359" xyz="0 0 0"/>
      <geometry>
        <mesh filename="package://franka_description/meshes/visual/finger.dae"/>
      </geometry>
    </visual>
    <collision>
      <origin rpy="0 0 3.14159265359" xyz="0 0 0"/>
      <geometry>
        <mesh filename="package://franka_description/meshes/collision/finger.stl"/>
      </geometry>
    </collision>
    <inertial>
      <origin rpy="0 0 3.14159265359" xyz="0 0 0"/>
      <mass value="0.1"/>
      <inertia ixx="0.1" ixy="0.0" ixz="0.0" iyy="0.1" iyz="0.0" izz="0.1"/>
    </inertial>
  </link>
  <joint name="panda_1_finger_joint1" type="prismatic">
    <parent link="panda_1_hand"/>
    <child link="panda_1_leftfinger"/>
    <origin rpy="0 0 0" xyz="0 0 0.0584"/>
    <axis xyz="0 1 0"/>
    <limit effort="150" lower="0.0" upper="0.04" velocity="0.2"/>
  </joint>
  <joint name="panda_1_finger_joint2" type="prismatic">
    <parent link="panda_1_hand"/>
    <child link="panda_1_rightfinger"/>
    <origin rpy="0 0 0" xyz="0 0 0.0584"/>
    <axis xyz="0 -1 0"/>
    <limit effort="150" lower="0.0" upper="0.04" velocity="0.2"/>
  </joint>
  <joint name="panda_2_virtual_joint" type="fixed">
    <parent link="robot2_pedestal_link"/>
    <child link="panda_2_link0"/>
    <origin rpy="0 0 0" xyz="0 0 0.95"/>
    <dynamics damping="1.0"/>
  </joint>
  <link name="panda_2_link0">
    <visual>
      <geometry>
        <mesh filename="package://franka_description/meshes/visual/link0.dae"/>
      </geometry>
    </visual>
    <collision>
      <geometry>
        <mesh filename="package://franka_description/meshes/collision/link0.stl"/>
      </geometry>
    </collision>
    <inertial>
      <origin rpy="0 0 0" xyz="0 0 0"/>
      <mass value="3.06"/>
      <inertia ixx="0.3" ixy="0.0" ixz="0.0" iyy="0.3" iyz="0.0" izz="0.3"/>
    </inertial>
  </link>
  <link name="panda_2_link1">
    <visual>
      <geometry>
        <mesh filename="package://franka_description/meshes/visual/link1.dae"/>
      </geometry>
    </visual>
    <collision>
      <geometry>
        <mesh filename="package://franka_description/meshes/collision/link1.stl"/>
      </geometry>
    </collision>
    <inertial>
      <origin rpy="0 0 0" xyz="0 0 0"/>
      <mass value="2.34"/>
      <inertia ixx="0.3" ixy="0.0" ixz="0.0" iyy="0.3" iyz="0.0" izz="0.3"/>
    </inertial>
  </link>
  <link name="panda_2_link2">
    <visual>
      <geometry>
        <mesh filename="package://franka_description/meshes/visual/link2.dae"/>
      </geometry>
    </visual>
    <collision>
      <geometry>
        <mesh filename="package://franka_description/meshes/collision/link2.stl"/>
      </geometry>
    </collision>
    <inertial>
      <origin rpy="0 0 0" xyz="0 0 0"/>
      <mass value="2.36"/>
      <inertia ixx="0.3" ixy="0.0" ixz="0.0" iyy="0.3" iyz="0.0" izz="0.3"/>
    </inertial>
  </link>
  <link name="panda_2_link3">
    <visual>
      <geometry>
        <mesh filename="package://franka_description/meshes/visual/link3.dae"/>
      </geometry>
    </visual>
    <collision>
      <geometry>
        <mesh filename="package://franka_description/meshes/collision/link3.stl"/>
      </geometry>
    </collision>
    <inertial>
      <origin rpy="0 0 0" xyz="0 0 0"/>
      <mass value="2.38"/>
      <inertia ixx="0.3" ixy="0.0" ixz="0.0" iyy="0.3" iyz="0.0" izz="0.3"/>
    </inertial>
  </link>
  <link name="panda_2_link4">
    <visual>
      <geometry>
        <mesh filename="package://franka_description/meshes/visual/link4.dae"/>
      </geometry>
    </visual>
    <collision>
      <geometry>
        <mesh filename="package://franka_description/meshes/collision/link4.stl"/>
      </geometry>
    </collision>
    <inertial>
      <origin rpy="0 0 0" xyz="0 0 0"/>
      <mass value="2.43"/>
      <inertia ixx="0.3" ixy="0.0" ixz="0.0" iyy="0.3" iyz="0.0" izz="0.3"/>
    </inertial>
  </link>
  <link name="panda_2_link5">
    <visual>
      <geometry>
        <mesh filename="package://franka_description/meshes/visual/link5.dae"/>
      </geometry>
    </visual>
    <collision>
      <geometry>
        <mesh filename="package://franka_description/meshes/collision/link5.stl"/>
      </geometry>
    </collision>
    <inertial>
      <origin rpy="0 0 0" xyz="0 0 0"/>
      <mass value="3.5"/>
      <inertia ixx="0.3" ixy="0.0" ixz="0.0" iyy="0.3" iyz="0.0" izz="0.3"/>
    </inertial>
  </link>
  <link name="panda_2_link6">
    <visual>
      <geometry>
        <mesh filename="package://franka_description/meshes/visual/link6.dae"/>
      </geometry>
    </visual>
    <collision>
      <geometry>
        <mesh filename="package://franka_description/meshes/collision/link6.stl"/>
      </geometry>
    </collision>
    <inertial>
      <origin rpy="0 0 0" xyz="0 0 0"/>
      <mass value="1.47"/>
      <inertia ixx="0.3" ixy="0.0" ixz="0.0" iyy="0.3" iyz="0.0" izz="0.3"/>
    </inertial>
  </link>
  <link name="panda_2_link7">
    <visual>
      <geometry>
        <mesh filename="package://franka_description/meshes/visual/link7.dae"/>
      </geometry>
    </visual>
    <collision>
      <geometry>
        <mesh filename="package://franka_description/meshes/collision/link7.stl"/>
      </geometry>
    </collision>
    <inertial>
      <origin rpy="0 0 0" xyz="0 0 0"/>
      <mass value="0.45"/>
      <inertia ixx="0.3" ixy="0.0" ixz="0.0" iyy="0.3" iyz="0.0" izz="0.3"/>
    </inertial>
  </link>
  <link name="panda_2_link8">
    <inertial>
      <origin rpy="0 0 0" xyz="0 0 0"/>
      <mass value="0.0"/>
      <inertia ixx="0.3" ixy="0.0" ixz="0.0" iyy="0.3" iyz="0.0" izz="0.3"/>
    </inertial>
  </link>
  <joint name="panda_2_joint1" type="revolute">
    <safety_controller k_position="100.0" k_velocity="40.0" soft_lower_limit="-2.8973" soft_upper_limit="2.8973"/>
    <origin rpy="0 0 0" xyz="0 0 0.333"/>
    <parent link="panda_2_link0"/>
    <child link="panda_2_link1"/>
    <limit effort="87" lower="-2.8973" upper="2.8973" velocity="2.175"/>
    <axis xyz="0 0 1"/>
    <dynamics damping="1.0"/>
  </joint>
  <joint name="panda_2_joint2" type="revolute">
    <safety_controller k_position="100.0" k_velocity="40.0" soft_lower_limit="-1.7628" soft_upper_limit="1.7628"/>
    <origin rpy="-1.57079632679 0 0" xyz="0 0 0"/>
    <parent link="panda_2_link1"/>
    <child link="panda_2_link2"/>
    <limit effort="87" lower="-1.7628" upper="1.7628" velocity="2.175"/>
    <axis xyz="0 0 1"/>
    <dynamics damping="1.0"/>
  </joint>
  <joint name="panda_2_joint3" type="revolute">
    <safety_controller k_position="100.0" k_velocity="40.0" soft_lower_limit="-2.8973" soft_upper_limit="2.8973"/>
    <origin rpy="1.57079632679 0 0" xyz="0 -0.316 0"/>
    <parent link="panda_2_link2"/>
    <child link="panda_2_link3"/>
    <limit effort="87" lower="-2.8973" upper="2.8973" velocity="2.175"/>
    <axis xyz="0 0 1"/>
    <dynamics damping="1.0"/>
  </joint>
  <joint name="panda_2_joint4" type="revolute">
    <safety_controller k_position="100.0" k_velocity="40.0" soft_lower_limit="-3.0718" soft_upper_limit="-0.0698"/>
    <origin rpy="1.57079632679 0 0" xyz="0.0825 0 0"/>
    <parent link="panda_2_link3"/>
    <child link="panda_2_link4"/>
    <limit effort="87" lower="-3.0718" upper="-0.0698" velocity="2.175"/>
    <axis xyz="0 0 1"/>
    <dynamics damping="1.0"/>
  </joint>
  <joint name="panda_2_joint5" type="revolute">
    <safety_controller k_position="100.0" k_velocity="40.0" soft_lower_limit="-2.8973" soft_upper_limit="2.8973"/>
    <origin rpy="-1.57079632679 0 0" xyz="-0.0825 0.384 0"/>
    <parent link="panda_2_link4"/>
    <child link="panda_2_link5"/>
    <limit effort="12" lower="-2.8973" upper="2.8973" velocity="2.61"/>
    <axis xyz="0 0 1"/>
    <dynamics damping="1.0"/>
  </joint>
  <joint name="panda_2_joint6" type="revolute">
    <safety_controller k_position="100.0" k_velocity="40.0" soft_lower_limit="-0.0175" soft_upper_limit="3.7525"/>
    <origin rpy="1.57079632679 0 0" xyz="0 0 0"/>
    <parent link="panda_2_link5"/>
    <child link="panda_2_link6"/>
    <limit effort="12" lower="-0.0175" upper="3.7525" velocity="2.61"/>
    <axis xyz="0 0 1"/>
    <dynamics damping="1.0"/>
  </joint>
  <joint name="panda_2_joint7" type="revolute">
    <safety_controller k_position="100.0" k_velocity="40.0" soft_lower_limit="-2.8973" soft_upper_limit="2.8973"/>
    <origin rpy="1.57079632679 0 0" xyz="0.088 0 0"/>
    <parent link="panda_2_link6"/>
    <child link="panda_2_link7"/>
    <limit effort="12" lower="-2.8973" upper="2.8973" velocity="2.61"/>
    <axis xyz="0 0 1"/>
    <dynamics damping="1.0"/>
  </joint>
  <joint name="panda_2_joint8" type="fixed">
    <origin rpy="0 0 0" xyz="0 0 0.107"/>
    <parent link="panda_2_link7"/>
    <child link="panda_2_link8"/>
    <axis xyz="0 0 0"/>
    <dynamics damping="1.0"/>
  </joint>
  <joint name="panda_2_hand_joint" type="fixed">
    <parent link="panda_2_link8"/>
    <child link="panda_2_hand"/>
    <origin rpy="0 0 -0.785398163397" xyz="0 0 0"/>
  </joint>
  <link name="panda_2_hand">
    <visual>
      <geometry>
        <mesh filename="package://franka_description/meshes/visual/hand.dae"/>
      </geometry>
    </visual>
    <collision>
      <geometry>
        <mesh filename="package://franka_description/meshes/collision/hand.stl"/>
      </geometry>
    </collision>
    <inertial>
      <origin rpy="0 0 0" xyz="0 0 0"/>
      <mass value="0.48"/>
      <inertia ixx="0.1" ixy="0.0" ixz="0.0" iyy="0.1" iyz="0.0" izz="0.1"/>
    </inertial>
  </link>
  <link name="panda_2_leftfinger">
    <visual>
      <geometry>
        <mesh filename="package://franka_description/meshes/visual/finger.dae"/>
      </geometry>
    </visual>
    <collision>
      <geometry>
        <mesh filename="package://franka_description/meshes/collision/finger.stl"/>
      </geometry>
    </collision>
    <inertial>
      <origin rpy="0 0 0" xyz="0 0 0"/>
      <mass value="0.1"/>
      <inertia ixx="0.1" ixy="0.0" ixz="0.0" iyy="0.1" iyz="0.0" izz="0.1"/>
    </inertial>
  </link>
  <link name="panda_2_rightfinger">
    <visual>
      <origin rpy="0 0 3.14159265359" xyz="0 0 0"/>
      <geometry>
        <mesh filename="package://franka_description/meshes/visual/finger.dae"/>
      </geometry>
    </visual>
    <collision>
      <origin rpy="0 0 3.14159265359" xyz="0 0 0"/>
      <geometry>
        <mesh filename="package://franka_description/meshes/collision/finger.stl"/>
      </geometry>
    </collision>
    <inertial>
      <origin rpy="0 0 3.14159265359" xyz="0 0 0"/>
      <mass value="0.1"/>
      <inertia ixx="0.1" ixy="0.0" ixz="0.0" iyy="0.1" iyz="0.0" izz="0.1"/>
    </inertial>
  </link>
  <joint name="panda_2_finger_joint1" type="prismatic">
    <parent link="panda_2_hand"/>
    <child link="panda_2_leftfinger"/>
    <origin rpy="0 0 0" xyz="0 0 0.0584"/>
    <axis xyz="0 1 0"/>
    <limit effort="150" lower="0.0" upper="0.04" velocity="0.2"/>
  </joint>
  <joint name="panda_2_finger_joint2" type="prismatic">
    <parent link="panda_2_hand"/>
    <child link="panda_2_rightfinger"/>
    <origin rpy="0 0 0" xyz="0 0 0.0584"/>
    <axis xyz="0 -1 0"/>
    <limit effort="150" lower="0.0" upper="0.04" velocity="0.2"/>
  </joint>
  <gazebo reference="panda_1_link0">
    <material>Gazebo/White</material>
    <mu1>0.2</mu1>
    <mu2>0.2</mu2>
  </gazebo>
  <gazebo reference="panda_1_link1">
    <material>Gazebo/White</material>
    <mu1>0.2</mu1>
    <mu2>0.2</mu2>
  </gazebo>
  <gazebo reference="panda_1_link2">
    <material>Gazebo/White</material>
    <mu1>0.2</mu1>
    <mu2>0.2</mu2>
  </gazebo>
  <gazebo reference="panda_1_link3">
    <material>Gazebo/White</material>
    <mu1>0.2</mu1>
    <mu2>0.2</mu2>
  </gazebo>
  <gazebo reference="panda_1_link4">
    <material>Gazebo/White</material>
    <mu1>0.2</mu1>
    <mu2>0.2</mu2>
  </gazebo>
  <gazebo reference="panda_1_link5">
    <material>Gazebo/White</material>
    <mu1>0.2</mu1>
    <mu2>0.2</mu2>
  </gazebo>
  <gazebo reference="panda_1_link6">
    <material>Gazebo/White</material>
    <mu1>0.2</mu1>
    <mu2>0.2</mu2>
  </gazebo>
  <gazebo reference="panda_1_link7">
    <material>Gazebo/White</material>
    <mu1>0.2</mu1>
    <mu2>0.2</mu2>
  </gazebo>
  <gazebo reference="panda_1_link8">
    <material>Gazebo/White</material>
    <mu1>0.2</mu1>
    <mu2>0.2</mu2>
  </gazebo>
  <transmission name="panda_1_tran_1">
    <type>transmission_interface/SimpleTransmission</type>
    <joint name="panda_1_joint1">
      <hardwareInterface>hardware_interface/EffortJointInterface</hardwareInterface>
    </joint>
    <actuator name="panda_1_motor_1">
      <hardwareInterface>hardware_interface/EffortJointInterface</hardwareInterface>
      <mechanicalReduction>1</mechanicalReduction>
    </actuator>
  </transmission>
  <transmission name="panda_1_tran_2">
    <type>transmission_interface/SimpleTransmission</type>
    <joint name="panda_1_joint2">
      <hardwareInterface>hardware_interface/EffortJointInterface</hardwareInterface>
    </joint>
    <actuator name="panda_1_motor_2">
      <hardwareInterface>hardware_interface/EffortJointInterface</hardwareInterface>
      <mechanicalReduction>1</mechanicalReduction>
    </actuator>
  </transmission>
  <transmission name="panda_1_tran_3">
    <type>transmission_interface/SimpleTransmission</type>
    <joint name="panda_1_joint3">
      <hardwareInterface>hardware_interface/EffortJointInterface</hardwareInterface>
    </joint>
    <actuator name="panda_1_motor_3">
      <hardwareInterface>hardware_interface/EffortJointInterface</hardwareInterface>
      <mechanicalReduction>1</mechanicalReduction>
    </actuator>
  </transmission>
  <transmission name="panda_1_tran_4">
    <type>transmission_interface/SimpleTransmission</type>
    <joint name="panda_1_joint4">
      <hardwareInterface>hardware_interface/EffortJointInterface</hardwareInterface>
    </joint>
    <actuator name="panda_1_motor_4">
      <hardwareInterface>hardware_interface/EffortJointInterface</hardwareInterface>
      <mechanicalReduction>1</mechanicalReduction>
    </actuator>
  </transmission>
  <transmission name="panda_1_tran_5">
    <type>transmission_interface/SimpleTransmission</type>
    <joint name="panda_1_joint5">
      <hardwareInterface>hardware_interface/EffortJointInterface</hardwareInterface>
    </joint>
    <actuator name="panda_1_motor_5">
      <hardwareInterface>hardware_interface/EffortJointInterface</hardwareInterface>
      <mechanicalReduction>1</mechanicalReduction>
    </actuator>
  </transmission>
  <transmission name="panda_1_tran_6">
    <type>transmission_interface/SimpleTransmission</type>
    <joint name="panda_1_joint6">
      <hardwareInterface>hardware_interface/EffortJointInterface</hardwareInterface>
    </joint>
    <actuator name="panda_1_motor_6">
      <hardwareInterface>hardware_interface/EffortJointInterface</hardwareInterface>
      <mechanicalReduction>1</mechanicalReduction>
    </actuator>
  </transmission>
  <transmission name="panda_1_tran_7">
    <type>transmission_interface/SimpleTransmission</type>
    <joint name="panda_1_joint7">
      <hardwareInterface>hardware_interface/EffortJointInterface</hardwareInterface>
    </joint>
    <actuator name="panda_1_motor_7">
      <hardwareInterface>hardware_interface/EffortJointInterface</hardwareInterface>
      <mechanicalReduction>1</mechanicalReduction>
    </actuator>
  </transmission>
  <gazebo reference="panda_1_hand">
    <material>Gazebo/Grey</material>
    <mu1>50</mu1>
    <mu2>50</mu2>
    <maxVel>0.001</maxVel>
    <!-- Default: 0.01, Description: maximum contact correction velocity truncation term. -->
    <minDepth>0.001</minDepth>
    <!-- Default: 0.0 meter, Description: minimum allowable depth before contact correction impulse is applied -->
  </gazebo>
  <gazebo reference="panda_1_rightfinger">
    <material>Gazebo/Grey</material>
    <mu1>50</mu1>
    <mu2>50</mu2>
    <maxVel>0.001</maxVel>
    <!-- Default: 0.01, Description: maximum contact correction velocity truncation term. -->
    <minDepth>0.001</minDepth>
    <!-- Default: 0.0 meter, Description: minimum allowable depth before contact correction impulse is applied -->
  </gazebo>
  <gazebo reference="panda_1_leftfinger">
    <material>Gazebo/Grey</material>
    <mu1>50</mu1>
    <mu2>50</mu2>
    <maxVel>0.001</maxVel>
    <!-- Default: 0.01, Description: maximum contact correction velocity truncation term. -->
    <minDepth>0.001</minDepth>
    <!-- Default: 0.0 meter, Description: minimum allowable depth before contact correction impulse is applied -->
  </gazebo>
  <transmission name="panda_1_leftfinger">
    <type>transmission_interface/SimpleTransmission</type>
    <joint name="panda_1_finger_joint1">
      <hardwareInterface>hardware_interface/EffortJointInterface</hardwareInterface>
    </joint>
    <actuator name="panda_1_finger_joint1">
      <hardwareInterface>hardware_interface/EffortJointInterface</hardwareInterface>
      <mechanicalReduction>1</mechanicalReduction>
    </actuator>
  </transmission>
  <transmission name="panda_1_rightfinger">
    <type>transmission_interface/SimpleTransmission</type>
    <joint name="panda_1_finger_joint2">
      <hardwareInterface>hardware_interface/EffortJointInterface</hardwareInterface>
    </joint>
    <actuator name="panda_1_finger_joint2">
      <hardwareInterface>hardware_interface/EffortJointInterface</hardwareInterface>
      <mechanicalReduction>1</mechanicalReduction>
    </actuator>
  </transmission>
  <gazebo reference="panda_2_link0">
    <material>Gazebo/White</material>
    <mu1>0.2</mu1>
    <mu2>0.2</mu2>
  </gazebo>
  <gazebo reference="panda_2_link1">
    <material>Gazebo/White</material>
    <mu1>0.2</mu1>
    <mu2>0.2</mu2>
  </gazebo>
  <gazebo reference="panda_2_link2">
    <material>Gazebo/White</material>
    <mu1>0.2</mu1>
    <mu2>0.2</mu2>
  </gazebo>
  <gazebo reference="panda_2_link3">
    <material>Gazebo/White</material>
    <mu1>0.2</mu1>
    <mu2>0.2</mu2>
  </gazebo>
  <gazebo reference="panda_2_link4">
    <material>Gazebo/White</material>
    <mu1>0.2</mu1>
    <mu2>0.2</mu2>
  </gazebo>
  <gazebo reference="panda_2_link5">
    <material>Gazebo/White</material>
    <mu1>0.2</mu1>
    <mu2>0.2</mu2>
  </gazebo>
  <gazebo reference="panda_2_link6">
    <material>Gazebo/White</material>
    <mu1>0.2</mu1>
    <mu2>0.2</mu2>
  </gazebo>
  <gazebo reference="panda_2_link7">
    <material>Gazebo/White</material>
    <mu1>0.2</mu1>
    <mu2>0.2</mu2>
  </gazebo>
  <gazebo reference="panda_2_link8">
    <material>Gazebo/White</material>
    <mu1>0.2</mu1>
    <mu2>0.2</mu2>
  </gazebo>
  <transmission name="panda_2_tran_1">
    <type>transmission_interface/SimpleTransmission</type>
    <joint name="panda_2_joint1">
      <hardwareInterface>hardware_interface/EffortJointInterface</hardwareInterface>
    </joint>
    <actuator name="panda_2_motor_1">
      <hardwareInterface>hardware_interface/EffortJointInterface</hardwareInterface>
      <mechanicalReduction>1</mechanicalReduction>
    </actuator>
  </transmission>
  <transmission name="panda_2_tran_2">
    <type>transmission_interface/SimpleTransmission</type>
    <joint name="panda_2_joint2">
      <hardwareInterface>hardware_interface/EffortJointInterface</hardwareInterface>
    </joint>
    <actuator name="panda_2_motor_2">
      <hardwareInterface>hardware_interface/EffortJointInterface</hardwareInterface>
      <mechanicalReduction>1</mechanicalReduction>
    </actuator>
  </transmission>
  <transmission name="panda_2_tran_3">
    <type>transmission_interface/SimpleTransmission</type>
    <joint name="panda_2_joint3">
      <hardwareInterface>hardware_interface/EffortJointInterface</hardwareInterface>
    </joint>
    <actuator name="panda_2_motor_3">
      <hardwareInterface>hardware_interface/EffortJointInterface</hardwareInterface>
      <mechanicalReduction>1</mechanicalReduction>
    </actuator>
  </transmission>
  <transmission name="panda_2_tran_4">
    <type>transmission_interface/SimpleTransmission</type>
    <joint name="panda_2_joint4">
      <hardwareInterface>hardware_interface/EffortJointInterface</hardwareInterface>
    </joint>
    <actuator name="panda_2_motor_4">
      <hardwareInterface>hardware_interface/EffortJointInterface</hardwareInterface>
      <mechanicalReduction>1</mechanicalReduction>
    </actuator>
  </transmission>
  <transmission name="panda_2_tran_5">
    <type>transmission_interface/SimpleTransmission</type>
    <joint name="panda_2_joint5">
      <hardwareInterface>hardware_interface/EffortJointInterface</hardwareInterface>
    </joint>
    <actuator name="panda_2_motor_5">
      <hardwareInterface>hardware_interface/EffortJointInterface</hardwareInterface>
      <mechanicalReduction>1</mechanicalReduction>
    </actuator>
  </transmission>
  <transmission name="panda_2_tran_6">
    <type>transmission_interface/SimpleTransmission</type>
    <joint name="panda_2_joint6">
      <hardwareInterface>hardware_interface/EffortJointInterface</hardwareInterface>
    </joint>
    <actuator name="panda_2_motor_6">
      <hardwareInterface>hardware_interface/EffortJointInterface</hardwareInterface>
      <mechanicalReduction>1</mechanicalReduction>
    </actuator>
  </transmission>
  <transmission name="panda_2_tran_7">
    <type>transmission_interface/SimpleTransmission</type>
    <joint name="panda_2_joint7">
      <hardwareInterface>hardware_interface/EffortJointInterface</hardwareInterface>
    </joint>
    <actuator name="panda_2_motor_7">
      <hardwareInterface>hardware_interface/EffortJointInterface</hardwareInterface>
      <mechanicalReduction>1</mechanicalReduction>
    </actuator>
  </transmission>
  <gazebo reference="panda_2_hand">
    <material>Gazebo/Grey</material>
    <mu1>50</mu1>
    <mu2>50</mu2>
    <maxVel>0.001</maxVel>
    <!-- Default: 0.01, Description: maximum contact correction velocity truncation term. -->
    <minDepth>0.001</minDepth>
    <!-- Default: 0.0 meter, Description: minimum allowable depth before contact correction impulse is applied -->
  </gazebo>
  <gazebo reference="panda_2_rightfinger">
    <material>Gazebo/Grey</material>
    <mu1>50</mu1>
    <mu2>50</mu2>
    <maxVel>0.001</maxVel>
    <!-- Default: 0.01, Description: maximum contact correction velocity truncation term. -->
    <minDepth>0.001</minDepth>
    <!-- Default: 0.0 meter, Description: minimum allowable depth before contact correction impulse is applied -->
  </gazebo>
  <gazebo reference="panda_2_leftfinger">
    <material>Gazebo/Grey</material>
    <mu1>50</mu1>
    <mu2>50</mu2>
    <maxVel>0.001</maxVel>
    <!-- Default: 0.01, Description: maximum contact correction velocity truncation term. -->
    <minDepth>0.001</minDepth>
    <!-- Default: 0.0 meter, Description: minimum allowable depth before contact correction impulse is applied -->
  </gazebo>
  <transmission name="panda_2_leftfinger">
    <type>transmission_interface/SimpleTransmission</type>
    <joint name="panda_2_finger_joint1">
      <hardwareInterface>hardware_interface/EffortJointInterface</hardwareInterface>
    </joint>
    <actuator name="panda_2_finger_joint1">
      <hardwareInterface>hardware_interface/EffortJointInterface</hardwareInterface>
      <mechanicalReduction>1</mechanicalReduction>
    </actuator>
  </transmission>
  <transmission name="panda_2_rightfinger">
    <type>transmission_interface/SimpleTransmission</type>
    <joint name="panda_2_finger_joint2">
      <hardwareInterface>hardware_interface/EffortJointInterface</hardwareInterface>
    </joint>
    <actuator name="panda_2_finger_joint2">
      <hardwareInterface>hardware_interface/EffortJointInterface</hardwareInterface>
      <mechanicalReduction>1</mechanicalReduction>
    </actuator>
  </transmission>
  <gazebo>
    <plugin filename="libgazebo_ros_control.so" name="gazebo_ros_control"/>
  </gazebo>
  <!-- ==================================================== -->
  <!-- Robot 1,2 pedestal -->
  <!-- ==================================================== -->
  <joint name="robot1_pedestal_joint" type="fixed">
    <origin rpy="0 0 0" xyz="-3.6 11.6 0.0"/>
    <parent link="world_interface"/>
    <child link="robot1_pedestal_link"/>
  </joint>
  <link name="robot1_pedestal_link">
    <visual>
      <origin xyz="0 0 0.475"/>
      <geometry>
        <box size="0.3 0.3 0.95"/>
      </geometry>
      <material name="pedestal_color">
        <color rgba="0 0.156862745098 0.525490196078 1"/>
      </material>
    </visual>
    <collision>
      <origin xyz="0 0 0.475"/>
      <geometry>
        <box size="0.3 0.3 0.95"/>
      </geometry>
    </collision>
    <inertial>
      <mass value="500"/>
      <origin rpy="0 0 0" xyz="0 0 0"/>
      <inertia ixx="0.001" ixy="0" ixz="0" iyy="0.001" iyz="0" izz="0.001"/>
    </inertial>
  </link>
  <gazebo reference="robot1_pedestal_link">
    <material>Gazebo/Blue</material>
  </gazebo>
  <joint name="robot2_pedestal_joint" type="fixed">
    <origin rpy="0 0 0" xyz="-3.6 7.6 0.0"/>
    <parent link="world_interface"/>
    <child link="robot2_pedestal_link"/>
  </joint>
  <link name="robot2_pedestal_link">
    <visual>
      <origin xyz="0 0 0.475"/>
      <geometry>
        <box size="0.3 0.3 0.95"/>
      </geometry>
      <material name="pedestal_color">
        <color rgba="0 0.156862745098 0.525490196078 1"/>
      </material>
    </visual>
    <collision>
      <origin xyz="0 0 0.475"/>
      <geometry>
        <box size="0.3 0.3 0.95"/>
      </geometry>
    </collision>
    <inertial>
      <mass value="500"/>
      <origin rpy="0 0 0" xyz="0 0 0"/>
      <inertia ixx="0.001" ixy="0" ixz="0" iyy="0.001" iyz="0" izz="0.001"/>
    </inertial>
  </link>
  <gazebo reference="robot2_pedestal_link">
    <material>Gazebo/Blue</material>
  </gazebo>
  <!-- link list -->
  <link name="bin_1_base_link">
    <visual>
      <origin rpy="0 0 0" xyz="0 0 0"/>
      <geometry>
        <mesh filename="package://omtp_support/meshes/bin/visual/bin.dae"/>
        <scale>0.6 0.6 0.6</scale>
      </geometry>
    </visual>
    <collision>
      <origin rpy="0 0 0" xyz="0 0 0"/>
      <geometry>
        <mesh filename="package://omtp_support/meshes/bin/collision/bin_bottom.dae"/>
        <scale>0.6 0.6 0.6</scale>
      </geometry>
    </collision>
    <collision>
      <origin rpy="0 0 0" xyz="0 0 0"/>
      <geometry>
        <mesh filename="package://omtp_support/meshes/bin/collision/bin_sides.dae"/>
        <scale>0.6 0.6 0.6</scale>
      </geometry>
    </collision>
    <inertial>
      <origin rpy="0 0 0" xyz="0 0 0"/>
      <inertia ixx="1.0" ixy="0" ixz="0" iyy="1.0" iyz="0" izz="1.0"/>
      <mass value="100"/>
    </inertial>
  </link>
  <link name="bin_1_drop_point">
    <inertial>
      <origin rpy="0 0 0" xyz="0 0 0"/>
      <inertia ixx="1.0" ixy="0" ixz="0" iyy="1.0" iyz="0" izz="1.0"/>
      <mass value="1.0"/>
    </inertial>
  </link>
  <!-- joint list -->
  <joint name="bin_1_joint_1" type="fixed">
    <origin rpy="0 0 0" xyz="0 0 1.0"/>
    <parent link="bin_1_base_link"/>
    <child link="bin_1_drop_point"/>
  </joint>
  <!-- link list -->
  <link name="bin_2_base_link">
    <visual>
      <origin rpy="0 0 0" xyz="0 0 0"/>
      <geometry>
        <mesh filename="package://omtp_support/meshes/bin/visual/bin.dae"/>
        <scale>0.6 0.6 0.6</scale>
      </geometry>
    </visual>
    <collision>
      <origin rpy="0 0 0" xyz="0 0 0"/>
      <geometry>
        <mesh filename="package://omtp_support/meshes/bin/collision/bin_bottom.dae"/>
        <scale>0.6 0.6 0.6</scale>
      </geometry>
    </collision>
    <collision>
      <origin rpy="0 0 0" xyz="0 0 0"/>
      <geometry>
        <mesh filename="package://omtp_support/meshes/bin/collision/bin_sides.dae"/>
        <scale>0.6 0.6 0.6</scale>
      </geometry>
    </collision>
    <inertial>
      <origin rpy="0 0 0" xyz="0 0 0"/>
      <inertia ixx="1.0" ixy="0" ixz="0" iyy="1.0" iyz="0" izz="1.0"/>
      <mass value="100"/>
    </inertial>
  </link>
  <link name="bin_2_drop_point">
    <inertial>
      <origin rpy="0 0 0" xyz="0 0 0"/>
      <inertia ixx="1.0" ixy="0" ixz="0" iyy="1.0" iyz="0" izz="1.0"/>
      <mass value="1.0"/>
    </inertial>
  </link>
  <!-- joint list -->
  <joint name="bin_2_joint_1" type="fixed">
    <origin rpy="0 0 0" xyz="0 0 1.0"/>
    <parent link="bin_2_base_link"/>
    <child link="bin_2_drop_point"/>
  </joint>
  <!-- link list -->
  <link name="bin_3_base_link">
    <visual>
      <origin rpy="0 0 0" xyz="0 0 0"/>
      <geometry>
        <mesh filename="package://omtp_support/meshes/bin/visual/bin.dae"/>
        <scale>0.6 0.6 0.6</scale>
      </geometry>
    </visual>
    <collision>
      <origin rpy="0 0 0" xyz="0 0 0"/>
      <geometry>
        <mesh filename="package://omtp_support/meshes/bin/collision/bin_bottom.dae"/>
        <scale>0.6 0.6 0.6</scale>
      </geometry>
    </collision>
    <collision>
      <origin rpy="0 0 0" xyz="0 0 0"/>
      <geometry>
        <mesh filename="package://omtp_support/meshes/bin/collision/bin_sides.dae"/>
        <scale>0.6 0.6 0.6</scale>
      </geometry>
    </collision>
    <inertial>
      <origin rpy="0 0 0" xyz="0 0 0"/>
      <inertia ixx="1.0" ixy="0" ixz="0" iyy="1.0" iyz="0" izz="1.0"/>
      <mass value="100"/>
    </inertial>
  </link>
  <link name="bin_3_drop_point">
    <inertial>
      <origin rpy="0 0 0" xyz="0 0 0"/>
      <inertia ixx="1.0" ixy="0" ixz="0" iyy="1.0" iyz="0" izz="1.0"/>
      <mass value="1.0"/>
    </inertial>
  </link>
  <!-- joint list -->
  <joint name="bin_3_joint_1" type="fixed">
    <origin rpy="0 0 0" xyz="0 0 1.0"/>
    <parent link="bin_3_base_link"/>
    <child link="bin_3_drop_point"/>
  </joint>
  <!-- link list -->
  <link name="bin_4_base_link">
    <visual>
      <origin rpy="0 0 0" xyz="0 0 0"/>
      <geometry>
        <mesh filename="package://omtp_support/meshes/bin/visual/bin.dae"/>
        <scale>0.6 0.6 0.6</scale>
      </geometry>
    </visual>
    <collision>
      <origin rpy="0 0 0" xyz="0 0 0"/>
      <geometry>
        <mesh filename="package://omtp_support/meshes/bin/collision/bin_bottom.dae"/>
        <scale>0.6 0.6 0.6</scale>
      </geometry>
    </collision>
    <collision>
      <origin rpy="0 0 0" xyz="0 0 0"/>
      <geometry>
        <mesh filename="package://omtp_support/meshes/bin/collision/bin_sides.dae"/>
        <scale>0.6 0.6 0.6</scale>
      </geometry>
    </collision>
    <inertial>
      <origin rpy="0 0 0" xyz="0 0 0"/>
      <inertia ixx="1.0" ixy="0" ixz="0" iyy="1.0" iyz="0" izz="1.0"/>
      <mass value="100"/>
    </inertial>
  </link>
  <link name="bin_4_drop_point">
    <inertial>
      <origin rpy="0 0 0" xyz="0 0 0"/>
      <inertia ixx="1.0" ixy="0" ixz="0" iyy="1.0" iyz="0" izz="1.0"/>
      <mass value="1.0"/>
    </inertial>
  </link>
  <!-- joint list -->
  <joint name="bin_4_joint_1" type="fixed">
    <origin rpy="0 0 0" xyz="0 0 1.0"/>
    <parent link="bin_4_base_link"/>
    <child link="bin_4_drop_point"/>
  </joint>
  <!-- link list -->
  <link name="bin_5_base_link">
    <visual>
      <origin rpy="0 0 0" xyz="0 0 0"/>
      <geometry>
        <mesh filename="package://omtp_support/meshes/bin/visual/bin.dae"/>
        <scale>0.6 0.6 0.6</scale>
      </geometry>
    </visual>
    <collision>
      <origin rpy="0 0 0" xyz="0 0 0"/>
      <geometry>
        <mesh filename="package://omtp_support/meshes/bin/collision/bin_bottom.dae"/>
        <scale>0.6 0.6 0.6</scale>
      </geometry>
    </collision>
    <collision>
      <origin rpy="0 0 0" xyz="0 0 0"/>
      <geometry>
        <mesh filename="package://omtp_support/meshes/bin/collision/bin_sides.dae"/>
        <scale>0.6 0.6 0.6</scale>
      </geometry>
    </collision>
    <inertial>
      <origin rpy="0 0 0" xyz="0 0 0"/>
      <inertia ixx="1.0" ixy="0" ixz="0" iyy="1.0" iyz="0" izz="1.0"/>
      <mass value="100"/>
    </inertial>
  </link>
  <link name="bin_5_drop_point">
    <inertial>
      <origin rpy="0 0 0" xyz="0 0 0"/>
      <inertia ixx="1.0" ixy="0" ixz="0" iyy="1.0" iyz="0" izz="1.0"/>
      <mass value="1.0"/>
    </inertial>
  </link>
  <!-- joint list -->
  <joint name="bin_5_joint_1" type="fixed">
    <origin rpy="0 0 0" xyz="0 0 1.0"/>
    <parent link="bin_5_base_link"/>
    <child link="bin_5_drop_point"/>
  </joint>
  <!-- Bin 1 -->
  <joint name="bin_1_joint" type="fixed">
    <parent link="world_interface"/>
    <child link="bin_1_base_link"/>
    <origin rpy="0 0 0" xyz="-2 12 0.0"/>
  </joint>
  <!-- Bin 2 -->
  <joint name="bin_2_joint" type="fixed">
    <parent link="world_interface"/>
    <child link="bin_2_base_link"/>
    <origin rpy="0 0 0" xyz="-4.25 10.3 0.0"/>
  </joint>
  <!-- Bin 3 -->
  <joint name="bin_3_joint" type="fixed">
    <parent link="world_interface"/>
    <child link="bin_3_base_link"/>
    <origin rpy="0 0 0" xyz="-4.2 9.0 0.0"/>
  </joint>
  <!-- Bin 4 -->
  <joint name="bin_4_joint" type="fixed">
    <parent link="world_interface"/>
    <child link="bin_4_base_link"/>
    <origin rpy="0 0 0" xyz="-0.7 7.0 0.0"/>
  </joint>
  <!-- Bin 5 -->
  <joint name="bin_5_joint" type="fixed">
    <parent link="world_interface"/>
    <child link="bin_5_base_link"/>
    <origin rpy="0 0 -1.57079632679" xyz="-4.0 7.0 0.0"/>
  </joint>
  <!-- Links -->
  <link name="bottle_1bottle">
    <visual>
      <geometry>
        <mesh filename="package://omtp_support/meshes/bottle/beer_bottle.dae"/>
      </geometry>
    </visual>
    <collision>
      <geometry>
        <mesh filename="package://omtp_support/meshes/bottle/beer_bottle.dae"/>
      </geometry>
    </collision>
    <inertial>
      <inertia ixx="1.0" ixy="0" ixz="0" iyy="1.0" iyz="0" izz="1.0"/>
      <mass value="10"/>
    </inertial>
  </link>
  <joint name="bottle_1bottle_interface" type="fixed">
    <origin rpy="0 0 0" xyz="-3.0 8.3 0.95"/>
    <parent link="world_interface"/>
    <child link="bottle_1bottle"/>
    <!-- <origin xyz="0 0 0" rpy="0 0 0" /> -->
  </joint>
  <!-- Links -->
  <link name="bottle_3bottle">
    <visual>
      <geometry>
        <mesh filename="package://omtp_support/meshes/bottle/beer_bottle.dae"/>
      </geometry>
    </visual>
    <collision>
      <geometry>
        <mesh filename="package://omtp_support/meshes/bottle/beer_bottle.dae"/>
      </geometry>
    </collision>
    <inertial>
      <inertia ixx="1.0" ixy="0" ixz="0" iyy="1.0" iyz="0" izz="1.0"/>
      <mass value="10"/>
    </inertial>
  </link>
  <joint name="bottle_3bottle_interface" type="fixed">
    <origin rpy="0 0 0" xyz="-3.0 11.4 0.95"/>
    <parent link="world_interface"/>
    <child link="bottle_3bottle"/>
    <!-- <origin xyz="0 0 0" rpy="0 0 0" /> -->
  </joint>
  <!-- Links -->
  <link name="bottle_4bottle">
    <visual>
      <geometry>
        <mesh filename="package://omtp_support/meshes/bottle/beer_bottle.dae"/>
      </geometry>
    </visual>
    <collision>
      <geometry>
        <mesh filename="package://omtp_support/meshes/bottle/beer_bottle.dae"/>
      </geometry>
    </collision>
    <inertial>
      <inertia ixx="1.0" ixy="0" ixz="0" iyy="1.0" iyz="0" izz="1.0"/>
      <mass value="10"/>
    </inertial>
  </link>
  <joint name="bottle_4bottle_interface" type="fixed">
    <origin rpy="0 0 0" xyz="-3.0 11.7 0.95"/>
    <parent link="world_interface"/>
    <child link="bottle_4bottle"/>
    <!-- <origin xyz="0 0 0" rpy="0 0 0" /> -->
  </joint>
  <!-- ==================================================== -->
  <!-- Festo Modules -->
  <!-- ==================================================== -->
  <!-- Links -->
  <link name="festo_bypass_1festo_module">
    <visual>
      <geometry>
        <mesh filename="package://aau_lab_ros_models/meshes/festo_bypass_module/festo_bypass_module.dae"/>
      </geometry>
    </visual>
    <collision>
      <geometry>
        <mesh filename="package://aau_lab_ros_models/meshes/festo_bypass_module/festo_bypass_module.dae"/>
      </geometry>
    </collision>
    <inertial>
      <inertia ixx="1.0" ixy="0" ixz="0" iyy="1.0" iyz="0" izz="1.0"/>
      <mass value="100"/>
    </inertial>
  </link>
  <joint name="festo_bypass_1festo_module_to_world_interface" type="fixed">
    <origin rpy="0 0 0" xyz="-3.0 11.45 0.0"/>
    <parent link="world_interface"/>
    <child link="festo_bypass_1festo_module"/>
    <!-- <origin xyz="0 0 0" rpy="0 0 0" /> -->
  </joint>
  <!-- Links -->
  <link name="festo_robot_1festo_module">
    <visual>
      <geometry>
        <mesh filename="package://aau_lab_ros_models/meshes/festo_robot_module/festo_robot_module.dae"/>
      </geometry>
    </visual>
    <collision>
      <geometry>
        <mesh filename="package://aau_lab_ros_models/meshes/festo_robot_module/festo_robot_module.dae"/>
      </geometry>
    </collision>
    <inertial>
      <inertia ixx="1.0" ixy="0" ixz="0" iyy="1.0" iyz="0" izz="1.0"/>
      <mass value="100"/>
    </inertial>
  </link>
  <joint name="festo_robot_1festo_module_to_world_interface" type="fixed">
    <origin rpy="0 0 0" xyz="-3.0 10.3 0.0"/>
    <parent link="world_interface"/>
    <child link="festo_robot_1festo_module"/>
    <!-- <origin xyz="0 0 0" rpy="0 0 0" /> -->
  </joint>
  <!-- Links -->
  <link name="festo_straight_1festo_module">
    <visual>
      <geometry>
        <mesh filename="package://aau_lab_ros_models/meshes/festo_straight_module/festo_straight_module.dae"/>
      </geometry>
    </visual>
    <collision>
      <geometry>
        <mesh filename="package://aau_lab_ros_models/meshes/festo_straight_module/festo_straight_module.dae"/>
      </geometry>
    </collision>
    <inertial>
      <inertia ixx="1.0" ixy="0" ixz="0" iyy="1.0" iyz="0" izz="1.0"/>
      <mass value="100"/>
    </inertial>
  </link>
  <joint name="festo_straight_1festo_module_to_world_interface" type="fixed">
    <origin rpy="0 0 0" xyz="-3.0 8.0 0.0"/>
    <parent link="world_interface"/>
    <child link="festo_straight_1festo_module"/>
    <!-- <origin xyz="0 0 0" rpy="0 0 0" /> -->
  </joint>
  <!-- Links -->
  <link name="festo_straight_2festo_module">
    <visual>
      <geometry>
        <mesh filename="package://aau_lab_ros_models/meshes/festo_straight_module/festo_straight_module.dae"/>
      </geometry>
    </visual>
    <collision>
      <geometry>
        <mesh filename="package://aau_lab_ros_models/meshes/festo_straight_module/festo_straight_module.dae"/>
      </geometry>
    </collision>
    <inertial>
      <inertia ixx="1.0" ixy="0" ixz="0" iyy="1.0" iyz="0" izz="1.0"/>
      <mass value="100"/>
    </inertial>
  </link>
  <joint name="festo_straight_2festo_module_to_world_interface" type="fixed">
    <origin rpy="0 0 0" xyz="-3.0 9.15 0.0"/>
    <parent link="world_interface"/>
    <child link="festo_straight_2festo_module"/>
    <!-- <origin xyz="0 0 0" rpy="0 0 0" /> -->
  </joint>
  <!-- Links -->
  <link name="festo_straight_3festo_module">
    <visual>
      <geometry>
        <mesh filename="package://aau_lab_ros_models/meshes/festo_straight_module/festo_straight_module.dae"/>
      </geometry>
    </visual>
    <collision>
      <geometry>
        <mesh filename="package://aau_lab_ros_models/meshes/festo_straight_module/festo_straight_module.dae"/>
      </geometry>
    </collision>
    <inertial>
      <inertia ixx="1.0" ixy="0" ixz="0" iyy="1.0" iyz="0" izz="1.0"/>
      <mass value="100"/>
    </inertial>
  </link>
  <joint name="festo_straight_3festo_module_to_world_interface" type="fixed">
    <origin rpy="0 0 0" xyz="-3.0 10.30 0.0"/>
    <parent link="world_interface"/>
    <child link="festo_straight_3festo_module"/>
    <!-- <origin xyz="0 0 0" rpy="0 0 0" /> -->
  </joint>
  <!-- Links -->
  <link name="festo_t_1festo_module">
    <visual>
      <geometry>
        <mesh filename="package://aau_lab_ros_models/meshes/festo_t_module/festo_t_module.dae"/>
      </geometry>
    </visual>
    <collision>
      <geometry>
        <mesh filename="package://aau_lab_ros_models/meshes/festo_t_module/festo_t_module.dae"/>
      </geometry>
    </collision>
    <inertial>
      <inertia ixx="1.0" ixy="0" ixz="0" iyy="1.0" iyz="0" izz="1.0"/>
      <mass value="100"/>
    </inertial>
  </link>
  <joint name="festo_t_1festo_module_to_world_interface" type="fixed">
    <origin rpy="0 0 -1.57079632679" xyz="-3.0 7.0 0.0"/>
    <parent link="world_interface"/>
    <child link="festo_t_1festo_module"/>
    <!-- <origin xyz="0 0 0" rpy="0 0 0" /> -->
  </joint>
  <!-- Links -->
  <link name="festo_straight_4festo_module">
    <visual>
      <geometry>
        <mesh filename="package://aau_lab_ros_models/meshes/festo_t_module/festo_t_module.dae"/>
      </geometry>
    </visual>
    <collision>
      <geometry>
        <mesh filename="package://aau_lab_ros_models/meshes/festo_t_module/festo_t_module.dae"/>
      </geometry>
    </collision>
    <inertial>
      <inertia ixx="1.0" ixy="0" ixz="0" iyy="1.0" iyz="0" izz="1.0"/>
      <mass value="100"/>
    </inertial>
  </link>
  <joint name="festo_straight_4festo_module_to_world_interface" type="fixed">
    <origin rpy="0 0 -1.57079632679" xyz="-1.84 7.0 0.0"/>
    <parent link="world_interface"/>
    <child link="festo_straight_4festo_module"/>
    <!-- <origin xyz="0 0 0" rpy="0 0 0" /> -->
  </joint>
</robot>

