<?xml version="1.0" encoding="utf-8"?>
<!-- =================================================================================== -->
<!-- |    This document was autogenerated by xacro from omtp_factory.xacro             | -->
<!-- |    EDITING THIS FILE BY HAND IS NOT RECOMMENDED                                 | -->
<!-- =================================================================================== -->
<robot name="omtp">
  <!-- ==================================================== -->
  <!-- INITIAL SETUP OF WORLD LINK AND WORLD_INTERFACE LINK -->
  <!-- ==================================================== -->
  <!-- world -->
  <link name="world"/>
  <!-- world_interface. Makes it convenient to move the whole environment according to the world origin -->
  <link name="world_interface"/>
  <!-- world<->world_interface joint -->
  <joint name="world_interface_to_world" type="fixed">
    <parent link="world"/>
    <child link="world_interface"/>
  </joint>
  <!-- Links -->
  <link name="fib14">
    <visual>
      <geometry>
        <mesh filename="package://aau_lab_ros_models/meshes/fib14/fib14.dae"/>
      </geometry>
    </visual>
    <collision>
      <geometry>
        <mesh filename="package://aau_lab_ros_models/meshes/fib14/fib14.dae"/>
      </geometry>
    </collision>
    <inertial>
      <inertia ixx="1.0" ixy="0" ixz="0" iyy="1.0" iyz="0" izz="1.0"/>
      <mass value="100"/>
    </inertial>
  </link>
  <joint name="fib14_to_world_interface" type="fixed">
    <parent link="world_interface"/>
    <child link="fib14"/>
    <origin rpy="0 0 0" xyz="0 0 0"/>
  </joint>
  <joint name="panda_1_virtual_joint" type="fixed">
    <parent link="robot1_pedestal_link"/>
    <child link="panda_1_link0"/>
    <origin rpy="0 0 0" xyz="0 0 0.95"/>
  </joint>
  <link name="panda_1_link0">
    <visual>
      <geometry>
        <mesh filename="package://franka_description/meshes/visual/link0.dae"/>
      </geometry>
    </visual>
    <collision>
      <origin rpy="0 0 0" xyz="0 0 -0.1915"/>
      <geometry>
        <cylinder length="0.2830" radius="0.09"/>
      </geometry>
    </collision>
    <collision>
      <origin rpy="0 0 0" xyz="0 0 -0.333"/>
      <geometry>
        <sphere radius="0.09"/>
      </geometry>
    </collision>
    <collision>
      <origin rpy="0 0 0" xyz="0 0 -0.05"/>
      <geometry>
        <sphere radius="0.09"/>
      </geometry>
    </collision>
  </link>
  <link name="panda_1_link1">
    <visual>
      <geometry>
        <mesh filename="package://franka_description/meshes/visual/link1.dae"/>
      </geometry>
    </visual>
    <collision>
      <origin rpy="0 0 0" xyz="0 0 -0.1915"/>
      <geometry>
        <cylinder length="0.2830" radius="0.09"/>
      </geometry>
    </collision>
    <collision>
      <origin rpy="0 0 0" xyz="0 0 -0.333"/>
      <geometry>
        <sphere radius="0.09"/>
      </geometry>
    </collision>
    <collision>
      <origin rpy="0 0 0" xyz="0 0 -0.05"/>
      <geometry>
        <sphere radius="0.09"/>
      </geometry>
    </collision>
  </link>
  <link name="panda_1_link2">
    <visual>
      <geometry>
        <mesh filename="package://franka_description/meshes/visual/link2.dae"/>
      </geometry>
    </visual>
    <collision>
      <origin rpy="0 0 0" xyz="0 0 0"/>
      <geometry>
        <cylinder length="0.12" radius="0.09"/>
      </geometry>
    </collision>
    <collision>
      <origin rpy="0 0 0" xyz="0 0 -0.06"/>
      <geometry>
        <sphere radius="0.09"/>
      </geometry>
    </collision>
    <collision>
      <origin rpy="0 0 0" xyz="0 0 0.06"/>
      <geometry>
        <sphere radius="0.09"/>
      </geometry>
    </collision>
  </link>
  <link name="panda_1_link3">
    <visual>
      <geometry>
        <mesh filename="package://franka_description/meshes/visual/link3.dae"/>
      </geometry>
    </visual>
    <collision>
      <origin rpy="0 0 0" xyz="0 0 -0.145"/>
      <geometry>
        <cylinder length="0.15" radius="0.09"/>
      </geometry>
    </collision>
    <collision>
      <origin rpy="0 0 0" xyz="0 0 -0.22"/>
      <geometry>
        <sphere radius="0.09"/>
      </geometry>
    </collision>
    <collision>
      <origin rpy="0 0 0" xyz="0 0 -0.07"/>
      <geometry>
        <sphere radius="0.09"/>
      </geometry>
    </collision>
  </link>
  <link name="panda_1_link4">
    <visual>
      <geometry>
        <mesh filename="package://franka_description/meshes/visual/link4.dae"/>
      </geometry>
    </visual>
    <collision>
      <origin rpy="0 0 0" xyz="0 0 0"/>
      <geometry>
        <cylinder length="0.12" radius="0.09"/>
      </geometry>
    </collision>
    <collision>
      <origin rpy="0 0 0" xyz="0 0 0.06"/>
      <geometry>
        <sphere radius="0.09"/>
      </geometry>
    </collision>
    <collision>
      <origin rpy="0 0 0" xyz="0 0 -0.06"/>
      <geometry>
        <sphere radius="0.09"/>
      </geometry>
    </collision>
  </link>
  <link name="panda_1_link5">
    <visual>
      <geometry>
        <mesh filename="package://franka_description/meshes/visual/link5.dae"/>
      </geometry>
    </visual>
    <collision>
      <origin rpy="0 0 0" xyz="0 0 -0.26"/>
      <geometry>
        <cylinder length="0.1" radius="0.09"/>
      </geometry>
    </collision>
    <collision>
      <origin rpy="0 0 0" xyz="0 0 -0.31"/>
      <geometry>
        <sphere radius="0.09"/>
      </geometry>
    </collision>
    <collision>
      <origin rpy="0 0 0" xyz="0 0 -0.21"/>
      <geometry>
        <sphere radius="0.09"/>
      </geometry>
    </collision>
    <collision>
      <origin rpy="0 0 0" xyz="0 0.08 -0.13"/>
      <geometry>
        <cylinder length="0.14" radius="0.055"/>
      </geometry>
    </collision>
    <collision>
      <origin rpy="0 0 0" xyz="0 0.08 -0.06"/>
      <geometry>
        <sphere radius="0.055"/>
      </geometry>
    </collision>
    <collision>
      <origin rpy="0 0 0" xyz="0 0.08 -0.20"/>
      <geometry>
        <sphere radius="0.055"/>
      </geometry>
    </collision>
  </link>
  <link name="panda_1_link6">
    <visual>
      <geometry>
        <mesh filename="package://franka_description/meshes/visual/link6.dae"/>
      </geometry>
    </visual>
    <collision>
      <origin rpy="0 0 0" xyz="0 0 -0.03"/>
      <geometry>
        <cylinder length="0.08" radius="0.08"/>
      </geometry>
    </collision>
    <collision>
      <origin rpy="0 0 0" xyz="0 0 0.01"/>
      <geometry>
        <sphere radius="0.08"/>
      </geometry>
    </collision>
    <collision>
      <origin rpy="0 0 0" xyz="0 0 -0.07"/>
      <geometry>
        <sphere radius="0.08"/>
      </geometry>
    </collision>
  </link>
  <link name="panda_1_link7">
    <visual>
      <geometry>
        <mesh filename="package://franka_description/meshes/visual/link7.dae"/>
      </geometry>
    </visual>
    <collision>
      <origin rpy="0 0 0" xyz="0 0 0.01"/>
      <geometry>
        <cylinder length="0.14" radius="0.07"/>
      </geometry>
    </collision>
    <collision>
      <origin rpy="0 0 0" xyz="0 0 0.08"/>
      <geometry>
        <sphere radius="0.07"/>
      </geometry>
    </collision>
    <collision>
      <origin rpy="0 0 0" xyz="0 0 -0.06"/>
      <geometry>
        <sphere radius="0.07"/>
      </geometry>
    </collision>
  </link>
  <link name="panda_1_link8">
    <collision>
      <origin rpy="3.14159265359 1.57079632679 1.57079632679" xyz="0.0424 0.0424 -0.0250"/>
      <geometry>
        <cylinder length="0.01" radius="0.06"/>
      </geometry>
    </collision>
    <collision>
      <origin rpy="0 0 0" xyz="0.0424 0.0424 -0.02"/>
      <geometry>
        <sphere radius="0.06"/>
      </geometry>
    </collision>
    <collision>
      <origin rpy="0 0 0" xyz="0.0424 0.0424 -0.03"/>
      <geometry>
        <sphere radius="0.06"/>
      </geometry>
    </collision>
  </link>
  <joint name="panda_1_joint1" type="revolute">
    <safety_controller k_position="100.0" k_velocity="40.0" soft_lower_limit="-2.8973" soft_upper_limit="2.8973"/>
    <origin rpy="0 0 0" xyz="0 0 0.333"/>
    <parent link="panda_1_link0"/>
    <child link="panda_1_link1"/>
    <limit effort="87" lower="-2.8973" upper="2.8973" velocity="2.175"/>
    <axis xyz="0 0 1"/>
    <dynamics damping="1.0"/>
  </joint>
  <joint name="panda_1_joint2" type="revolute">
    <safety_controller k_position="100.0" k_velocity="40.0" soft_lower_limit="-1.7628" soft_upper_limit="1.7628"/>
    <origin rpy="-1.57079632679 0 0" xyz="0 0 0"/>
    <parent link="panda_1_link1"/>
    <child link="panda_1_link2"/>
    <limit effort="87" lower="-1.7628" upper="1.7628" velocity="2.175"/>
    <axis xyz="0 0 1"/>
    <dynamics damping="1.0"/>
  </joint>
  <joint name="panda_1_joint3" type="revolute">
    <safety_controller k_position="100.0" k_velocity="40.0" soft_lower_limit="-2.8973" soft_upper_limit="2.8973"/>
    <origin rpy="1.57079632679 0 0" xyz="0 -0.316 0"/>
    <parent link="panda_1_link2"/>
    <child link="panda_1_link3"/>
    <limit effort="87" lower="-2.8973" upper="2.8973" velocity="2.175"/>
    <axis xyz="0 0 1"/>
    <dynamics damping="1.0"/>
  </joint>
  <joint name="panda_1_joint4" type="revolute">
    <safety_controller k_position="100.0" k_velocity="40.0" soft_lower_limit="-3.0718" soft_upper_limit="-0.0698"/>
    <origin rpy="1.57079632679 0 0" xyz="0.0825 0 0"/>
    <parent link="panda_1_link3"/>
    <child link="panda_1_link4"/>
    <limit effort="87" lower="-3.0718" upper="-0.0698" velocity="2.175"/>
    <axis xyz="0 0 1"/>
    <dynamics damping="1.0"/>
  </joint>
  <joint name="panda_1_joint5" type="revolute">
    <safety_controller k_position="100.0" k_velocity="40.0" soft_lower_limit="-2.8973" soft_upper_limit="2.8973"/>
    <origin rpy="-1.57079632679 0 0" xyz="-0.0825 0.384 0"/>
    <parent link="panda_1_link4"/>
    <child link="panda_1_link5"/>
    <limit effort="12" lower="-2.8973" upper="2.8973" velocity="2.61"/>
    <axis xyz="0 0 1"/>
    <dynamics damping="1.0"/>
  </joint>
  <joint name="panda_1_joint6" type="revolute">
    <safety_controller k_position="100.0" k_velocity="40.0" soft_lower_limit="-0.0175" soft_upper_limit="3.7525"/>
    <origin rpy="1.57079632679 0 0" xyz="0 0 0"/>
    <parent link="panda_1_link5"/>
    <child link="panda_1_link6"/>
    <limit effort="12" lower="-0.0175" upper="3.7525" velocity="2.61"/>
    <axis xyz="0 0 1"/>
    <dynamics damping="1.0"/>
  </joint>
  <joint name="panda_1_joint7" type="revolute">
    <safety_controller k_position="100.0" k_velocity="40.0" soft_lower_limit="-2.8973" soft_upper_limit="2.8973"/>
    <origin rpy="1.57079632679 0 0" xyz="0.088 0 0"/>
    <parent link="panda_1_link6"/>
    <child link="panda_1_link7"/>
    <limit effort="12" lower="-2.8973" upper="2.8973" velocity="2.61"/>
    <axis xyz="0 0 1"/>
    <dynamics damping="1.0"/>
  </joint>
  <joint name="panda_1_joint8" type="fixed">
    <origin rpy="0 0 0" xyz="0 0 0.107"/>
    <parent link="panda_1_link7"/>
    <child link="panda_1_link8"/>
    <axis xyz="0 0 0"/>
    <dynamics damping="1.0"/>
  </joint>
  <joint name="panda_1_hand_joint" type="fixed">
    <parent link="panda_1_link8"/>
    <child link="panda_1_hand"/>
    <origin rpy="0 0 -0.785398163397" xyz="0 0 0"/>
  </joint>
  <link name="panda_1_hand">
    <visual>
      <geometry>
        <mesh filename="package://franka_description/meshes/visual/hand.dae"/>
      </geometry>
    </visual>
    <collision>
      <origin rpy="0 1.57079632679 1.57079632679" xyz="0 0 0.04"/>
      <geometry>
        <cylinder length="0.1" radius="0.07"/>
      </geometry>
    </collision>
    <collision>
      <origin rpy="0 0 0" xyz="0 -0.05 0.04"/>
      <geometry>
        <sphere radius="0.07"/>
      </geometry>
    </collision>
    <collision>
      <origin rpy="0 0 0" xyz="0 0.05 0.04"/>
      <geometry>
        <sphere radius="0.07"/>
      </geometry>
    </collision>
    <collision>
      <origin rpy="0 1.57079632679 1.57079632679" xyz="0 0 0.1"/>
      <geometry>
        <cylinder length="0.1" radius="0.05"/>
      </geometry>
    </collision>
    <collision>
      <origin rpy="0 0 0" xyz="0 -0.05 0.1"/>
      <geometry>
        <sphere radius="0.05"/>
      </geometry>
    </collision>
    <collision>
      <origin rpy="0 0 0" xyz="0 0.05 0.1"/>
      <geometry>
        <sphere radius="0.05"/>
      </geometry>
    </collision>
  </link>
  <link name="panda_1_leftfinger">
    <visual>
      <geometry>
        <mesh filename="package://franka_description/meshes/visual/finger.dae"/>
      </geometry>
    </visual>
  </link>
  <link name="panda_1_rightfinger">
    <visual>
      <origin rpy="0 0 3.14159265359" xyz="0 0 0"/>
      <geometry>
        <mesh filename="package://franka_description/meshes/visual/finger.dae"/>
      </geometry>
    </visual>
  </link>
  <joint name="panda_1_finger_joint1" type="prismatic">
    <parent link="panda_1_hand"/>
    <child link="panda_1_leftfinger"/>
    <origin rpy="0 0 0" xyz="0 0 0.0584"/>
    <axis xyz="0 1 0"/>
    <limit effort="150" lower="0.0" upper="0.04" velocity="0.2"/>
  </joint>
  <joint name="panda_1_finger_joint2" type="prismatic">
    <parent link="panda_1_hand"/>
    <child link="panda_1_rightfinger"/>
    <origin rpy="0 0 0" xyz="0 0 0.0584"/>
    <axis xyz="0 -1 0"/>
    <limit effort="150" lower="0.0" upper="0.04" velocity="0.2"/>
    <mimic joint="panda_1_finger_joint1"/>
  </joint>
  <joint name="panda_3_virtual_joint" type="fixed">
    <parent link="robot2_pedestal_link"/>
    <child link="panda_3_link0"/>
    <origin rpy="0 0 0" xyz="0 0 0.95"/>
  </joint>
  <link name="panda_3_link0">
    <visual>
      <geometry>
        <mesh filename="package://franka_description/meshes/visual/link0.dae"/>
      </geometry>
    </visual>
    <collision>
      <origin rpy="0 0 0" xyz="0 0 -0.1915"/>
      <geometry>
        <cylinder length="0.2830" radius="0.09"/>
      </geometry>
    </collision>
    <collision>
      <origin rpy="0 0 0" xyz="0 0 -0.333"/>
      <geometry>
        <sphere radius="0.09"/>
      </geometry>
    </collision>
    <collision>
      <origin rpy="0 0 0" xyz="0 0 -0.05"/>
      <geometry>
        <sphere radius="0.09"/>
      </geometry>
    </collision>
  </link>
  <link name="panda_3_link1">
    <visual>
      <geometry>
        <mesh filename="package://franka_description/meshes/visual/link1.dae"/>
      </geometry>
    </visual>
    <collision>
      <origin rpy="0 0 0" xyz="0 0 -0.1915"/>
      <geometry>
        <cylinder length="0.2830" radius="0.09"/>
      </geometry>
    </collision>
    <collision>
      <origin rpy="0 0 0" xyz="0 0 -0.333"/>
      <geometry>
        <sphere radius="0.09"/>
      </geometry>
    </collision>
    <collision>
      <origin rpy="0 0 0" xyz="0 0 -0.05"/>
      <geometry>
        <sphere radius="0.09"/>
      </geometry>
    </collision>
  </link>
  <link name="panda_3_link2">
    <visual>
      <geometry>
        <mesh filename="package://franka_description/meshes/visual/link2.dae"/>
      </geometry>
    </visual>
    <collision>
      <origin rpy="0 0 0" xyz="0 0 0"/>
      <geometry>
        <cylinder length="0.12" radius="0.09"/>
      </geometry>
    </collision>
    <collision>
      <origin rpy="0 0 0" xyz="0 0 -0.06"/>
      <geometry>
        <sphere radius="0.09"/>
      </geometry>
    </collision>
    <collision>
      <origin rpy="0 0 0" xyz="0 0 0.06"/>
      <geometry>
        <sphere radius="0.09"/>
      </geometry>
    </collision>
  </link>
  <link name="panda_3_link3">
    <visual>
      <geometry>
        <mesh filename="package://franka_description/meshes/visual/link3.dae"/>
      </geometry>
    </visual>
    <collision>
      <origin rpy="0 0 0" xyz="0 0 -0.145"/>
      <geometry>
        <cylinder length="0.15" radius="0.09"/>
      </geometry>
    </collision>
    <collision>
      <origin rpy="0 0 0" xyz="0 0 -0.22"/>
      <geometry>
        <sphere radius="0.09"/>
      </geometry>
    </collision>
    <collision>
      <origin rpy="0 0 0" xyz="0 0 -0.07"/>
      <geometry>
        <sphere radius="0.09"/>
      </geometry>
    </collision>
  </link>
  <link name="panda_3_link4">
    <visual>
      <geometry>
        <mesh filename="package://franka_description/meshes/visual/link4.dae"/>
      </geometry>
    </visual>
    <collision>
      <origin rpy="0 0 0" xyz="0 0 0"/>
      <geometry>
        <cylinder length="0.12" radius="0.09"/>
      </geometry>
    </collision>
    <collision>
      <origin rpy="0 0 0" xyz="0 0 0.06"/>
      <geometry>
        <sphere radius="0.09"/>
      </geometry>
    </collision>
    <collision>
      <origin rpy="0 0 0" xyz="0 0 -0.06"/>
      <geometry>
        <sphere radius="0.09"/>
      </geometry>
    </collision>
  </link>
  <link name="panda_3_link5">
    <visual>
      <geometry>
        <mesh filename="package://franka_description/meshes/visual/link5.dae"/>
      </geometry>
    </visual>
    <collision>
      <origin rpy="0 0 0" xyz="0 0 -0.26"/>
      <geometry>
        <cylinder length="0.1" radius="0.09"/>
      </geometry>
    </collision>
    <collision>
      <origin rpy="0 0 0" xyz="0 0 -0.31"/>
      <geometry>
        <sphere radius="0.09"/>
      </geometry>
    </collision>
    <collision>
      <origin rpy="0 0 0" xyz="0 0 -0.21"/>
      <geometry>
        <sphere radius="0.09"/>
      </geometry>
    </collision>
    <collision>
      <origin rpy="0 0 0" xyz="0 0.08 -0.13"/>
      <geometry>
        <cylinder length="0.14" radius="0.055"/>
      </geometry>
    </collision>
    <collision>
      <origin rpy="0 0 0" xyz="0 0.08 -0.06"/>
      <geometry>
        <sphere radius="0.055"/>
      </geometry>
    </collision>
    <collision>
      <origin rpy="0 0 0" xyz="0 0.08 -0.20"/>
      <geometry>
        <sphere radius="0.055"/>
      </geometry>
    </collision>
  </link>
  <link name="panda_3_link6">
    <visual>
      <geometry>
        <mesh filename="package://franka_description/meshes/visual/link6.dae"/>
      </geometry>
    </visual>
    <collision>
      <origin rpy="0 0 0" xyz="0 0 -0.03"/>
      <geometry>
        <cylinder length="0.08" radius="0.08"/>
      </geometry>
    </collision>
    <collision>
      <origin rpy="0 0 0" xyz="0 0 0.01"/>
      <geometry>
        <sphere radius="0.08"/>
      </geometry>
    </collision>
    <collision>
      <origin rpy="0 0 0" xyz="0 0 -0.07"/>
      <geometry>
        <sphere radius="0.08"/>
      </geometry>
    </collision>
  </link>
  <link name="panda_3_link7">
    <visual>
      <geometry>
        <mesh filename="package://franka_description/meshes/visual/link7.dae"/>
      </geometry>
    </visual>
    <collision>
      <origin rpy="0 0 0" xyz="0 0 0.01"/>
      <geometry>
        <cylinder length="0.14" radius="0.07"/>
      </geometry>
    </collision>
    <collision>
      <origin rpy="0 0 0" xyz="0 0 0.08"/>
      <geometry>
        <sphere radius="0.07"/>
      </geometry>
    </collision>
    <collision>
      <origin rpy="0 0 0" xyz="0 0 -0.06"/>
      <geometry>
        <sphere radius="0.07"/>
      </geometry>
    </collision>
  </link>
  <link name="panda_3_link8">
    <collision>
      <origin rpy="3.14159265359 1.57079632679 1.57079632679" xyz="0.0424 0.0424 -0.0250"/>
      <geometry>
        <cylinder length="0.01" radius="0.06"/>
      </geometry>
    </collision>
    <collision>
      <origin rpy="0 0 0" xyz="0.0424 0.0424 -0.02"/>
      <geometry>
        <sphere radius="0.06"/>
      </geometry>
    </collision>
    <collision>
      <origin rpy="0 0 0" xyz="0.0424 0.0424 -0.03"/>
      <geometry>
        <sphere radius="0.06"/>
      </geometry>
    </collision>
  </link>
  <joint name="panda_3_joint1" type="revolute">
    <safety_controller k_position="100.0" k_velocity="40.0" soft_lower_limit="-2.8973" soft_upper_limit="2.8973"/>
    <origin rpy="0 0 0" xyz="0 0 0.333"/>
    <parent link="panda_3_link0"/>
    <child link="panda_3_link1"/>
    <limit effort="87" lower="-2.8973" upper="2.8973" velocity="2.175"/>
    <axis xyz="0 0 1"/>
    <dynamics damping="1.0"/>
  </joint>
  <joint name="panda_3_joint2" type="revolute">
    <safety_controller k_position="100.0" k_velocity="40.0" soft_lower_limit="-1.7628" soft_upper_limit="1.7628"/>
    <origin rpy="-1.57079632679 0 0" xyz="0 0 0"/>
    <parent link="panda_3_link1"/>
    <child link="panda_3_link2"/>
    <limit effort="87" lower="-1.7628" upper="1.7628" velocity="2.175"/>
    <axis xyz="0 0 1"/>
    <dynamics damping="1.0"/>
  </joint>
  <joint name="panda_3_joint3" type="revolute">
    <safety_controller k_position="100.0" k_velocity="40.0" soft_lower_limit="-2.8973" soft_upper_limit="2.8973"/>
    <origin rpy="1.57079632679 0 0" xyz="0 -0.316 0"/>
    <parent link="panda_3_link2"/>
    <child link="panda_3_link3"/>
    <limit effort="87" lower="-2.8973" upper="2.8973" velocity="2.175"/>
    <axis xyz="0 0 1"/>
    <dynamics damping="1.0"/>
  </joint>
  <joint name="panda_3_joint4" type="revolute">
    <safety_controller k_position="100.0" k_velocity="40.0" soft_lower_limit="-3.0718" soft_upper_limit="-0.0698"/>
    <origin rpy="1.57079632679 0 0" xyz="0.0825 0 0"/>
    <parent link="panda_3_link3"/>
    <child link="panda_3_link4"/>
    <limit effort="87" lower="-3.0718" upper="-0.0698" velocity="2.175"/>
    <axis xyz="0 0 1"/>
    <dynamics damping="1.0"/>
  </joint>
  <joint name="panda_3_joint5" type="revolute">
    <safety_controller k_position="100.0" k_velocity="40.0" soft_lower_limit="-2.8973" soft_upper_limit="2.8973"/>
    <origin rpy="-1.57079632679 0 0" xyz="-0.0825 0.384 0"/>
    <parent link="panda_3_link4"/>
    <child link="panda_3_link5"/>
    <limit effort="12" lower="-2.8973" upper="2.8973" velocity="2.61"/>
    <axis xyz="0 0 1"/>
    <dynamics damping="1.0"/>
  </joint>
  <joint name="panda_3_joint6" type="revolute">
    <safety_controller k_position="100.0" k_velocity="40.0" soft_lower_limit="-0.0175" soft_upper_limit="3.7525"/>
    <origin rpy="1.57079632679 0 0" xyz="0 0 0"/>
    <parent link="panda_3_link5"/>
    <child link="panda_3_link6"/>
    <limit effort="12" lower="-0.0175" upper="3.7525" velocity="2.61"/>
    <axis xyz="0 0 1"/>
    <dynamics damping="1.0"/>
  </joint>
  <joint name="panda_3_joint7" type="revolute">
    <safety_controller k_position="100.0" k_velocity="40.0" soft_lower_limit="-2.8973" soft_upper_limit="2.8973"/>
    <origin rpy="1.57079632679 0 0" xyz="0.088 0 0"/>
    <parent link="panda_3_link6"/>
    <child link="panda_3_link7"/>
    <limit effort="12" lower="-2.8973" upper="2.8973" velocity="2.61"/>
    <axis xyz="0 0 1"/>
    <dynamics damping="1.0"/>
  </joint>
  <joint name="panda_3_joint8" type="fixed">
    <origin rpy="0 0 0" xyz="0 0 0.107"/>
    <parent link="panda_3_link7"/>
    <child link="panda_3_link8"/>
    <axis xyz="0 0 0"/>
    <dynamics damping="1.0"/>
  </joint>
  <joint name="panda_3_hand_joint" type="fixed">
    <parent link="panda_3_link8"/>
    <child link="panda_3_hand"/>
    <origin rpy="0 0 -0.785398163397" xyz="0 0 0"/>
  </joint>
  <link name="panda_3_hand">
    <visual>
      <geometry>
        <mesh filename="package://franka_description/meshes/visual/hand.dae"/>
      </geometry>
    </visual>
    <collision>
      <origin rpy="0 1.57079632679 1.57079632679" xyz="0 0 0.04"/>
      <geometry>
        <cylinder length="0.1" radius="0.07"/>
      </geometry>
    </collision>
    <collision>
      <origin rpy="0 0 0" xyz="0 -0.05 0.04"/>
      <geometry>
        <sphere radius="0.07"/>
      </geometry>
    </collision>
    <collision>
      <origin rpy="0 0 0" xyz="0 0.05 0.04"/>
      <geometry>
        <sphere radius="0.07"/>
      </geometry>
    </collision>
    <collision>
      <origin rpy="0 1.57079632679 1.57079632679" xyz="0 0 0.1"/>
      <geometry>
        <cylinder length="0.1" radius="0.05"/>
      </geometry>
    </collision>
    <collision>
      <origin rpy="0 0 0" xyz="0 -0.05 0.1"/>
      <geometry>
        <sphere radius="0.05"/>
      </geometry>
    </collision>
    <collision>
      <origin rpy="0 0 0" xyz="0 0.05 0.1"/>
      <geometry>
        <sphere radius="0.05"/>
      </geometry>
    </collision>
  </link>
  <link name="panda_3_leftfinger">
    <visual>
      <geometry>
        <mesh filename="package://franka_description/meshes/visual/finger.dae"/>
      </geometry>
    </visual>
  </link>
  <link name="panda_3_rightfinger">
    <visual>
      <origin rpy="0 0 3.14159265359" xyz="0 0 0"/>
      <geometry>
        <mesh filename="package://franka_description/meshes/visual/finger.dae"/>
      </geometry>
    </visual>
  </link>
  <joint name="panda_3_finger_joint1" type="prismatic">
    <parent link="panda_3_hand"/>
    <child link="panda_3_leftfinger"/>
    <origin rpy="0 0 0" xyz="0 0 0.0584"/>
    <axis xyz="0 1 0"/>
    <limit effort="150" lower="0.0" upper="0.04" velocity="0.2"/>
  </joint>
  <joint name="panda_3_finger_joint2" type="prismatic">
    <parent link="panda_3_hand"/>
    <child link="panda_3_rightfinger"/>
    <origin rpy="0 0 0" xyz="0 0 0.0584"/>
    <axis xyz="0 -1 0"/>
    <limit effort="150" lower="0.0" upper="0.04" velocity="0.2"/>
    <mimic joint="panda_3_finger_joint1"/>
  </joint>
  <!-- ==================================================== -->
  <!-- Robot 1,2 pedestal -->
  <!-- ==================================================== -->
  <joint name="robot1_pedestal_joint" type="fixed">
    <origin rpy="0 0 0" xyz="-3.6 11.6 0.0"/>
    <parent link="world_interface"/>
    <child link="robot1_pedestal_link"/>
  </joint>
  <link name="robot1_pedestal_link">
    <visual>
      <origin xyz="0 0 0.475"/>
      <geometry>
        <box size="0.3 0.3 0.95"/>
      </geometry>
      <material name="pedestal_color">
        <color rgba="0 0.156862745098 0.525490196078 1"/>
      </material>
    </visual>
    <collision>
      <origin xyz="0 0 0.475"/>
      <geometry>
        <box size="0.3 0.3 0.95"/>
      </geometry>
    </collision>
    <inertial>
      <mass value="500"/>
      <origin rpy="0 0 0" xyz="0 0 0"/>
      <inertia ixx="0.001" ixy="0" ixz="0" iyy="0.001" iyz="0" izz="0.001"/>
    </inertial>
  </link>
  <gazebo reference="robot1_pedestal_link">
    <material>Gazebo/Blue</material>
  </gazebo>
  <joint name="robot2_pedestal_joint" type="fixed">
    <origin rpy="0 0 0" xyz="-3.6 7.6 0.0"/>
    <parent link="world_interface"/>
    <child link="robot2_pedestal_link"/>
  </joint>
  <link name="robot2_pedestal_link">
    <visual>
      <origin xyz="0 0 0.475"/>
      <geometry>
        <box size="0.3 0.3 0.95"/>
      </geometry>
      <material name="pedestal_color">
        <color rgba="0 0.156862745098 0.525490196078 1"/>
      </material>
    </visual>
    <collision>
      <origin xyz="0 0 0.475"/>
      <geometry>
        <box size="0.3 0.3 0.95"/>
      </geometry>
    </collision>
    <inertial>
      <mass value="500"/>
      <origin rpy="0 0 0" xyz="0 0 0"/>
      <inertia ixx="0.001" ixy="0" ixz="0" iyy="0.001" iyz="0" izz="0.001"/>
    </inertial>
  </link>
  <gazebo reference="robot2_pedestal_link">
    <material>Gazebo/Blue</material>
  </gazebo>
  <!-- link list -->
  <link name="bin_1_base_link">
    <visual>
      <origin rpy="0 0 0" xyz="0 0 0"/>
      <geometry>
        <mesh filename="package://omtp_support/meshes/bin/visual/bin.dae"/>
        <scale>0.6 0.6 0.6</scale>
      </geometry>
    </visual>
    <collision>
      <origin rpy="0 0 0" xyz="0 0 0"/>
      <geometry>
        <mesh filename="package://omtp_support/meshes/bin/collision/bin_bottom.dae"/>
        <scale>0.6 0.6 0.6</scale>
      </geometry>
    </collision>
    <collision>
      <origin rpy="0 0 0" xyz="0 0 0"/>
      <geometry>
        <mesh filename="package://omtp_support/meshes/bin/collision/bin_sides.dae"/>
        <scale>0.6 0.6 0.6</scale>
      </geometry>
    </collision>
    <inertial>
      <origin rpy="0 0 0" xyz="0 0 0"/>
      <inertia ixx="1.0" ixy="0" ixz="0" iyy="1.0" iyz="0" izz="1.0"/>
      <mass value="100"/>
    </inertial>
  </link>
  <link name="bin_1_drop_point">
    <inertial>
      <origin rpy="0 0 0" xyz="0 0 0"/>
      <inertia ixx="1.0" ixy="0" ixz="0" iyy="1.0" iyz="0" izz="1.0"/>
      <mass value="1.0"/>
    </inertial>
  </link>
  <!-- joint list -->
  <joint name="bin_1_joint_1" type="fixed">
    <origin rpy="0 0 0" xyz="0 0 1.0"/>
    <parent link="bin_1_base_link"/>
    <child link="bin_1_drop_point"/>
  </joint>
  <!-- link list -->
  <link name="bin_2_base_link">
    <visual>
      <origin rpy="0 0 0" xyz="0 0 0"/>
      <geometry>
        <mesh filename="package://omtp_support/meshes/bin/visual/bin.dae"/>
        <scale>0.6 0.6 0.6</scale>
      </geometry>
    </visual>
    <collision>
      <origin rpy="0 0 0" xyz="0 0 0"/>
      <geometry>
        <mesh filename="package://omtp_support/meshes/bin/collision/bin_bottom.dae"/>
        <scale>0.6 0.6 0.6</scale>
      </geometry>
    </collision>
    <collision>
      <origin rpy="0 0 0" xyz="0 0 0"/>
      <geometry>
        <mesh filename="package://omtp_support/meshes/bin/collision/bin_sides.dae"/>
        <scale>0.6 0.6 0.6</scale>
      </geometry>
    </collision>
    <inertial>
      <origin rpy="0 0 0" xyz="0 0 0"/>
      <inertia ixx="1.0" ixy="0" ixz="0" iyy="1.0" iyz="0" izz="1.0"/>
      <mass value="100"/>
    </inertial>
  </link>
  <link name="bin_2_drop_point">
    <inertial>
      <origin rpy="0 0 0" xyz="0 0 0"/>
      <inertia ixx="1.0" ixy="0" ixz="0" iyy="1.0" iyz="0" izz="1.0"/>
      <mass value="1.0"/>
    </inertial>
  </link>
  <!-- joint list -->
  <joint name="bin_2_joint_1" type="fixed">
    <origin rpy="0 0 0" xyz="0 0 1.0"/>
    <parent link="bin_2_base_link"/>
    <child link="bin_2_drop_point"/>
  </joint>
  <!-- link list -->
  <link name="bin_3_base_link">
    <visual>
      <origin rpy="0 0 0" xyz="0 0 0"/>
      <geometry>
        <mesh filename="package://omtp_support/meshes/bin/visual/bin.dae"/>
        <scale>0.6 0.6 0.6</scale>
      </geometry>
    </visual>
    <collision>
      <origin rpy="0 0 0" xyz="0 0 0"/>
      <geometry>
        <mesh filename="package://omtp_support/meshes/bin/collision/bin_bottom.dae"/>
        <scale>0.6 0.6 0.6</scale>
      </geometry>
    </collision>
    <collision>
      <origin rpy="0 0 0" xyz="0 0 0"/>
      <geometry>
        <mesh filename="package://omtp_support/meshes/bin/collision/bin_sides.dae"/>
        <scale>0.6 0.6 0.6</scale>
      </geometry>
    </collision>
    <inertial>
      <origin rpy="0 0 0" xyz="0 0 0"/>
      <inertia ixx="1.0" ixy="0" ixz="0" iyy="1.0" iyz="0" izz="1.0"/>
      <mass value="100"/>
    </inertial>
  </link>
  <link name="bin_3_drop_point">
    <inertial>
      <origin rpy="0 0 0" xyz="0 0 0"/>
      <inertia ixx="1.0" ixy="0" ixz="0" iyy="1.0" iyz="0" izz="1.0"/>
      <mass value="1.0"/>
    </inertial>
  </link>
  <!-- joint list -->
  <joint name="bin_3_joint_1" type="fixed">
    <origin rpy="0 0 0" xyz="0 0 1.0"/>
    <parent link="bin_3_base_link"/>
    <child link="bin_3_drop_point"/>
  </joint>
  <!-- link list -->
  <link name="bin_4_base_link">
    <visual>
      <origin rpy="0 0 0" xyz="0 0 0"/>
      <geometry>
        <mesh filename="package://omtp_support/meshes/bin/visual/bin.dae"/>
        <scale>0.6 0.6 0.6</scale>
      </geometry>
    </visual>
    <collision>
      <origin rpy="0 0 0" xyz="0 0 0"/>
      <geometry>
        <mesh filename="package://omtp_support/meshes/bin/collision/bin_bottom.dae"/>
        <scale>0.6 0.6 0.6</scale>
      </geometry>
    </collision>
    <collision>
      <origin rpy="0 0 0" xyz="0 0 0"/>
      <geometry>
        <mesh filename="package://omtp_support/meshes/bin/collision/bin_sides.dae"/>
        <scale>0.6 0.6 0.6</scale>
      </geometry>
    </collision>
    <inertial>
      <origin rpy="0 0 0" xyz="0 0 0"/>
      <inertia ixx="1.0" ixy="0" ixz="0" iyy="1.0" iyz="0" izz="1.0"/>
      <mass value="100"/>
    </inertial>
  </link>
  <link name="bin_4_drop_point">
    <inertial>
      <origin rpy="0 0 0" xyz="0 0 0"/>
      <inertia ixx="1.0" ixy="0" ixz="0" iyy="1.0" iyz="0" izz="1.0"/>
      <mass value="1.0"/>
    </inertial>
  </link>
  <!-- joint list -->
  <joint name="bin_4_joint_1" type="fixed">
    <origin rpy="0 0 0" xyz="0 0 1.0"/>
    <parent link="bin_4_base_link"/>
    <child link="bin_4_drop_point"/>
  </joint>
  <!-- link list -->
  <link name="bin_5_base_link">
    <visual>
      <origin rpy="0 0 0" xyz="0 0 0"/>
      <geometry>
        <mesh filename="package://omtp_support/meshes/bin/visual/bin.dae"/>
        <scale>0.6 0.6 0.6</scale>
      </geometry>
    </visual>
    <collision>
      <origin rpy="0 0 0" xyz="0 0 0"/>
      <geometry>
        <mesh filename="package://omtp_support/meshes/bin/collision/bin_bottom.dae"/>
        <scale>0.6 0.6 0.6</scale>
      </geometry>
    </collision>
    <collision>
      <origin rpy="0 0 0" xyz="0 0 0"/>
      <geometry>
        <mesh filename="package://omtp_support/meshes/bin/collision/bin_sides.dae"/>
        <scale>0.6 0.6 0.6</scale>
      </geometry>
    </collision>
    <inertial>
      <origin rpy="0 0 0" xyz="0 0 0"/>
      <inertia ixx="1.0" ixy="0" ixz="0" iyy="1.0" iyz="0" izz="1.0"/>
      <mass value="100"/>
    </inertial>
  </link>
  <link name="bin_5_drop_point">
    <inertial>
      <origin rpy="0 0 0" xyz="0 0 0"/>
      <inertia ixx="1.0" ixy="0" ixz="0" iyy="1.0" iyz="0" izz="1.0"/>
      <mass value="1.0"/>
    </inertial>
  </link>
  <!-- joint list -->
  <joint name="bin_5_joint_1" type="fixed">
    <origin rpy="0 0 0" xyz="0 0 1.0"/>
    <parent link="bin_5_base_link"/>
    <child link="bin_5_drop_point"/>
  </joint>
  <!-- Bin 1 -->
  <joint name="bin_1_joint" type="fixed">
    <parent link="world_interface"/>
    <child link="bin_1_base_link"/>
    <origin rpy="0 0 0" xyz="-2 12 0.0"/>
  </joint>
  <!-- Bin 2 -->
  <joint name="bin_2_joint" type="fixed">
    <parent link="world_interface"/>
    <child link="bin_2_base_link"/>
    <origin rpy="0 0 0" xyz="-4.25 10.3 0.0"/>
  </joint>
  <!-- Bin 3 -->
  <joint name="bin_3_joint" type="fixed">
    <parent link="world_interface"/>
    <child link="bin_3_base_link"/>
    <origin rpy="0 0 0" xyz="-4.2 9.0 0.0"/>
  </joint>
  <!-- Bin 4 -->
  <joint name="bin_4_joint" type="fixed">
    <parent link="world_interface"/>
    <child link="bin_4_base_link"/>
    <origin rpy="0 0 0" xyz="-0.7 7.0 0.0"/>
  </joint>
  <!-- Bin 5 -->
  <joint name="bin_5_joint" type="fixed">
    <parent link="world_interface"/>
    <child link="bin_5_base_link"/>
    <origin rpy="0 0 -1.57079632679" xyz="-4.0 7.0 0.0"/>
  </joint>
  <!-- ==================================================== -->
  <!-- Festo Modules -->
  <!-- ==================================================== -->
  <!-- Links -->
  <link name="festo_bypass_1festo_module">
    <visual>
      <geometry>
        <mesh filename="package://aau_lab_ros_models/meshes/festo_bypass_module/festo_bypass_module.dae"/>
      </geometry>
    </visual>
    <collision>
      <geometry>
        <mesh filename="package://aau_lab_ros_models/meshes/festo_bypass_module/festo_bypass_module.dae"/>
      </geometry>
    </collision>
    <inertial>
      <inertia ixx="1.0" ixy="0" ixz="0" iyy="1.0" iyz="0" izz="1.0"/>
      <mass value="100"/>
    </inertial>
  </link>
  <joint name="festo_bypass_1festo_module_to_world_interface" type="fixed">
    <origin rpy="0 0 0" xyz="-3.0 11.45 0.0"/>
    <parent link="world_interface"/>
    <child link="festo_bypass_1festo_module"/>
    <!-- <origin xyz="0 0 0" rpy="0 0 0" /> -->
  </joint>
  <!-- Links -->
  <link name="festo_robot_1festo_module">
    <visual>
      <geometry>
        <mesh filename="package://aau_lab_ros_models/meshes/festo_robot_module/festo_robot_module.dae"/>
      </geometry>
    </visual>
    <collision>
      <geometry>
        <mesh filename="package://aau_lab_ros_models/meshes/festo_robot_module/festo_robot_module.dae"/>
      </geometry>
    </collision>
    <inertial>
      <inertia ixx="1.0" ixy="0" ixz="0" iyy="1.0" iyz="0" izz="1.0"/>
      <mass value="100"/>
    </inertial>
  </link>
  <joint name="festo_robot_1festo_module_to_world_interface" type="fixed">
    <origin rpy="0 0 0" xyz="-3.0 10.3 0.0"/>
    <parent link="world_interface"/>
    <child link="festo_robot_1festo_module"/>
    <!-- <origin xyz="0 0 0" rpy="0 0 0" /> -->
  </joint>
  <!-- Links -->
  <link name="festo_straight_2festo_module">
    <visual>
      <geometry>
        <mesh filename="package://aau_lab_ros_models/meshes/festo_straight_module/festo_straight_module.dae"/>
      </geometry>
    </visual>
    <collision>
      <geometry>
        <mesh filename="package://aau_lab_ros_models/meshes/festo_straight_module/festo_straight_module.dae"/>
      </geometry>
    </collision>
    <inertial>
      <inertia ixx="1.0" ixy="0" ixz="0" iyy="1.0" iyz="0" izz="1.0"/>
      <mass value="100"/>
    </inertial>
  </link>
  <joint name="festo_straight_2festo_module_to_world_interface" type="fixed">
    <origin rpy="0 0 0" xyz="-3.0 8.0 0.0"/>
    <parent link="world_interface"/>
    <child link="festo_straight_2festo_module"/>
    <!-- <origin xyz="0 0 0" rpy="0 0 0" /> -->
  </joint>
  <!-- Links -->
  <link name="festo_straight_3festo_module">
    <visual>
      <geometry>
        <mesh filename="package://aau_lab_ros_models/meshes/festo_straight_module/festo_straight_module.dae"/>
      </geometry>
    </visual>
    <collision>
      <geometry>
        <mesh filename="package://aau_lab_ros_models/meshes/festo_straight_module/festo_straight_module.dae"/>
      </geometry>
    </collision>
    <inertial>
      <inertia ixx="1.0" ixy="0" ixz="0" iyy="1.0" iyz="0" izz="1.0"/>
      <mass value="100"/>
    </inertial>
  </link>
  <joint name="festo_straight_3festo_module_to_world_interface" type="fixed">
    <origin rpy="0 0 0" xyz="-3.0 9.15 0.0"/>
    <parent link="world_interface"/>
    <child link="festo_straight_3festo_module"/>
    <!-- <origin xyz="0 0 0" rpy="0 0 0" /> -->
  </joint>
  <!-- Links -->
  <link name="festo_straight_4festo_module">
    <visual>
      <geometry>
        <mesh filename="package://aau_lab_ros_models/meshes/festo_straight_module/festo_straight_module.dae"/>
      </geometry>
    </visual>
    <collision>
      <geometry>
        <mesh filename="package://aau_lab_ros_models/meshes/festo_straight_module/festo_straight_module.dae"/>
      </geometry>
    </collision>
    <inertial>
      <inertia ixx="1.0" ixy="0" ixz="0" iyy="1.0" iyz="0" izz="1.0"/>
      <mass value="100"/>
    </inertial>
  </link>
  <joint name="festo_straight_4festo_module_to_world_interface" type="fixed">
    <origin rpy="0 0 0" xyz="-3.0 10.30 0.0"/>
    <parent link="world_interface"/>
    <child link="festo_straight_4festo_module"/>
    <!-- <origin xyz="0 0 0" rpy="0 0 0" /> -->
  </joint>
  <!-- Links -->
  <link name="festo_t_1festo_module">
    <visual>
      <geometry>
        <mesh filename="package://aau_lab_ros_models/meshes/festo_t_module/festo_t_module.dae"/>
      </geometry>
    </visual>
    <collision>
      <geometry>
        <mesh filename="package://aau_lab_ros_models/meshes/festo_t_module/festo_t_module.dae"/>
      </geometry>
    </collision>
    <inertial>
      <inertia ixx="1.0" ixy="0" ixz="0" iyy="1.0" iyz="0" izz="1.0"/>
      <mass value="100"/>
    </inertial>
  </link>
  <joint name="festo_t_1festo_module_to_world_interface" type="fixed">
    <origin rpy="0 0 -1.57079632679" xyz="-3.0 7.0 0.0"/>
    <parent link="world_interface"/>
    <child link="festo_t_1festo_module"/>
    <!-- <origin xyz="0 0 0" rpy="0 0 0" /> -->
  </joint>
  <!-- Links -->
  <link name="festo_straight_1festo_module">
    <visual>
      <geometry>
        <mesh filename="package://aau_lab_ros_models/meshes/festo_straight_module/festo_straight_module.dae"/>
      </geometry>
    </visual>
    <collision>
      <geometry>
        <mesh filename="package://aau_lab_ros_models/meshes/festo_straight_module/festo_straight_module.dae"/>
      </geometry>
    </collision>
    <inertial>
      <inertia ixx="1.0" ixy="0" ixz="0" iyy="1.0" iyz="0" izz="1.0"/>
      <mass value="100"/>
    </inertial>
  </link>
  <joint name="festo_straight_1festo_module_to_world_interface" type="fixed">
    <origin rpy="0 0 -1.57079632679" xyz="-1.84 7.0 0.0"/>
    <parent link="world_interface"/>
    <child link="festo_straight_1festo_module"/>
    <!-- <origin xyz="0 0 0" rpy="0 0 0" /> -->
  </joint>
</robot>

