<?xml version="1.0" ?>
<!-- =================================================================================== -->
<!-- |    This document was autogenerated by xacro from /home/zouner16/catkin_ws/src/lecture5_files/omtp_lecture5/urdf/omtp_panda_2d_cam.urdf.xacro | -->
<!-- |    EDITING THIS FILE BY HAND IS NOT RECOMMENDED                                 | -->
<!-- =================================================================================== -->
<robot name="omtp">
    <!-- ==================================================== -->
    <!-- INITIAL SETUP OF WORLD LINK                          -->
    <!-- ==================================================== -->
    <!-- world -->
    <link name="world" />
    <!-- world_interface. Makes it convenient to move the whole environment according to the world origin -->
    <link name="world_interface" />
    <!-- world<->world_interface joint -->
    <joint name="world_interface_to_world" type="fixed">
        <parent link="world" />
        <child link="world_interface" />
    </joint>
    <!-- Links -->
    <link name="fib14">
        <visual>
            <geometry>
                <mesh filename="package://aau_lab_ros_models/meshes/fib14/fib14.dae" />
            </geometry>
        </visual>
        <collision>
            <geometry>
                <mesh filename="package://aau_lab_ros_models/meshes/fib14/fib14.dae" />
            </geometry>
        </collision>
        <inertial>
            <inertia ixx="1.0" ixy="0" ixz="0" iyy="1.0" iyz="0" izz="1.0" />
            <mass value="100" />
            <origin xyz="0 0 0" rpy="0 0 0" />
        </inertial>
    </link>
    <joint name="fib14_to_world_interface" type="fixed">
        <parent link="world_interface" />
        <child link="fib14" />
        <origin rpy="0 0 0" xyz="0 0 0" />
    </joint>
    <joint name="panda_virtual_joint" type="fixed">
        <parent link="world_interface" />
        <child link="panda_link0" />
        <origin rpy="0 0 0" xyz="0 0 0" />
        <dynamics damping="1.0" />
    </joint>
    <link name="panda_link0">
        <visual>
            <geometry>
                <mesh filename="package://franka_description/meshes/visual/link0.dae" />
            </geometry>
        </visual>
        <collision>
            <geometry>
                <mesh filename="package://franka_description/meshes/collision/link0.stl" />
            </geometry>
        </collision>
        <inertial>
            <origin rpy="0 0 0" xyz="0 0 0" />
            <mass value="3.06" />
            <inertia ixx="0.3" ixy="0.0" ixz="0.0" iyy="0.3" iyz="0.0" izz="0.3" />
        </inertial>
    </link>
    <link name="panda_link1">
        <visual>
            <geometry>
                <mesh filename="package://franka_description/meshes/visual/link1.dae" />
            </geometry>
        </visual>
        <collision>
            <geometry>
                <mesh filename="package://franka_description/meshes/collision/link1.stl" />
            </geometry>
        </collision>
        <inertial>
            <origin rpy="0 0 0" xyz="0 0 0" />
            <mass value="2.34" />
            <inertia ixx="0.3" ixy="0.0" ixz="0.0" iyy="0.3" iyz="0.0" izz="0.3" />
        </inertial>
    </link>
    <link name="panda_link2">
        <visual>
            <geometry>
                <mesh filename="package://franka_description/meshes/visual/link2.dae" />
            </geometry>
        </visual>
        <collision>
            <geometry>
                <mesh filename="package://franka_description/meshes/collision/link2.stl" />
            </geometry>
        </collision>
        <inertial>
            <origin rpy="0 0 0" xyz="0 0 0" />
            <mass value="2.36" />
            <inertia ixx="0.3" ixy="0.0" ixz="0.0" iyy="0.3" iyz="0.0" izz="0.3" />
        </inertial>
    </link>
    <link name="panda_link3">
        <visual>
            <geometry>
                <mesh filename="package://franka_description/meshes/visual/link3.dae" />
            </geometry>
        </visual>
        <collision>
            <geometry>
                <mesh filename="package://franka_description/meshes/collision/link3.stl" />
            </geometry>
        </collision>
        <inertial>
            <origin rpy="0 0 0" xyz="0 0 0" />
            <mass value="2.38" />
            <inertia ixx="0.3" ixy="0.0" ixz="0.0" iyy="0.3" iyz="0.0" izz="0.3" />
        </inertial>
    </link>
    <link name="panda_link4">
        <visual>
            <geometry>
                <mesh filename="package://franka_description/meshes/visual/link4.dae" />
            </geometry>
        </visual>
        <collision>
            <geometry>
                <mesh filename="package://franka_description/meshes/collision/link4.stl" />
            </geometry>
        </collision>
        <inertial>
            <origin rpy="0 0 0" xyz="0 0 0" />
            <mass value="2.43" />
            <inertia ixx="0.3" ixy="0.0" ixz="0.0" iyy="0.3" iyz="0.0" izz="0.3" />
        </inertial>
    </link>
    <link name="panda_link5">
        <visual>
            <geometry>
                <mesh filename="package://franka_description/meshes/visual/link5.dae" />
            </geometry>
        </visual>
        <collision>
            <geometry>
                <mesh filename="package://franka_description/meshes/collision/link5.stl" />
            </geometry>
        </collision>
        <inertial>
            <origin rpy="0 0 0" xyz="0 0 0" />
            <mass value="3.5" />
            <inertia ixx="0.3" ixy="0.0" ixz="0.0" iyy="0.3" iyz="0.0" izz="0.3" />
        </inertial>
    </link>
    <link name="panda_link6">
        <visual>
            <geometry>
                <mesh filename="package://franka_description/meshes/visual/link6.dae" />
            </geometry>
        </visual>
        <collision>
            <geometry>
                <mesh filename="package://franka_description/meshes/collision/link6.stl" />
            </geometry>
        </collision>
        <inertial>
            <origin rpy="0 0 0" xyz="0 0 0" />
            <mass value="1.47" />
            <inertia ixx="0.3" ixy="0.0" ixz="0.0" iyy="0.3" iyz="0.0" izz="0.3" />
        </inertial>
    </link>
    <link name="panda_link7">
        <visual>
            <geometry>
                <mesh filename="package://franka_description/meshes/visual/link7.dae" />
            </geometry>
        </visual>
        <collision>
            <geometry>
                <mesh filename="package://franka_description/meshes/collision/link7.stl" />
            </geometry>
        </collision>
        <inertial>
            <origin rpy="0 0 0" xyz="0 0 0" />
            <mass value="0.45" />
            <inertia ixx="0.3" ixy="0.0" ixz="0.0" iyy="0.3" iyz="0.0" izz="0.3" />
        </inertial>
    </link>
    <link name="panda_link8">
        <inertial>
            <origin rpy="0 0 0" xyz="0 0 0" />
            <mass value="0.0" />
            <inertia ixx="0.3" ixy="0.0" ixz="0.0" iyy="0.3" iyz="0.0" izz="0.3" />
        </inertial>
    </link>
    <joint name="panda_joint1" type="revolute">
        <safety_controller k_position="100.0" k_velocity="40.0" soft_lower_limit="-2.8973" soft_upper_limit="2.8973" />
        <origin rpy="0 0 0" xyz="0 0 0.333" />
        <parent link="panda_link0" />
        <child link="panda_link1" />
        <limit effort="87" lower="-2.8973" upper="2.8973" velocity="2.175" />
        <axis xyz="0 0 1" />
        <dynamics damping="1.0" />
    </joint>
    <joint name="panda_joint2" type="revolute">
        <safety_controller k_position="100.0" k_velocity="40.0" soft_lower_limit="-1.7628" soft_upper_limit="1.7628" />
        <origin rpy="-1.5707963267948966 0 0" xyz="0 0 0" />
        <parent link="panda_link1" />
        <child link="panda_link2" />
        <limit effort="87" lower="-1.7628" upper="1.7628" velocity="2.175" />
        <axis xyz="0 0 1" />
        <dynamics damping="1.0" />
    </joint>
    <joint name="panda_joint3" type="revolute">
        <safety_controller k_position="100.0" k_velocity="40.0" soft_lower_limit="-2.8973" soft_upper_limit="2.8973" />
        <origin rpy="1.5707963267948966 0 0" xyz="0 -0.316 0" />
        <parent link="panda_link2" />
        <child link="panda_link3" />
        <limit effort="87" lower="-2.8973" upper="2.8973" velocity="2.175" />
        <axis xyz="0 0 1" />
        <dynamics damping="1.0" />
    </joint>
    <joint name="panda_joint4" type="revolute">
        <safety_controller k_position="100.0" k_velocity="40.0" soft_lower_limit="-3.0718" soft_upper_limit="-0.0698" />
        <origin rpy="1.5707963267948966 0 0" xyz="0.0825 0 0" />
        <parent link="panda_link3" />
        <child link="panda_link4" />
        <limit effort="87" lower="-3.0718" upper="-0.0698" velocity="2.175" />
        <axis xyz="0 0 1" />
        <dynamics damping="1.0" />
    </joint>
    <joint name="panda_joint5" type="revolute">
        <safety_controller k_position="100.0" k_velocity="40.0" soft_lower_limit="-2.8973" soft_upper_limit="2.8973" />
        <origin rpy="-1.5707963267948966 0 0" xyz="-0.0825 0.384 0" />
        <parent link="panda_link4" />
        <child link="panda_link5" />
        <limit effort="12" lower="-2.8973" upper="2.8973" velocity="2.61" />
        <axis xyz="0 0 1" />
        <dynamics damping="1.0" />
    </joint>
    <joint name="panda_joint6" type="revolute">
        <safety_controller k_position="100.0" k_velocity="40.0" soft_lower_limit="-0.0175" soft_upper_limit="3.7525" />
        <origin rpy="1.5707963267948966 0 0" xyz="0 0 0" />
        <parent link="panda_link5" />
        <child link="panda_link6" />
        <limit effort="12" lower="-0.0175" upper="3.7525" velocity="2.61" />
        <axis xyz="0 0 1" />
        <dynamics damping="1.0" />
    </joint>
    <joint name="panda_joint7" type="revolute">
        <safety_controller k_position="100.0" k_velocity="40.0" soft_lower_limit="-2.8973" soft_upper_limit="2.8973" />
        <origin rpy="1.5707963267948966 0 0" xyz="0.088 0 0" />
        <parent link="panda_link6" />
        <child link="panda_link7" />
        <limit effort="12" lower="-2.8973" upper="2.8973" velocity="2.61" />
        <axis xyz="0 0 1" />
        <dynamics damping="1.0" />
    </joint>
    <joint name="panda_joint8" type="fixed">
        <origin rpy="0 0 0" xyz="0 0 0.107" />
        <parent link="panda_link7" />
        <child link="panda_link8" />
        <axis xyz="0 0 0" />
        <dynamics damping="1.0" />
    </joint>
    <gazebo reference="panda_link0">
        <material>Gazebo/White</material>
        <mu1>0.2</mu1>
        <mu2>0.2</mu2>
        <plugin name="gazebo_ros_control">
            <robotNamespace>/</robotNamespace>
        </plugin>
    </gazebo>
    <gazebo reference="panda_link1">
        <material>Gazebo/White</material>
        <mu1>0.2</mu1>
        <mu2>0.2</mu2>
    </gazebo>
    <gazebo reference="panda_link2">
        <material>Gazebo/White</material>
        <mu1>0.2</mu1>
        <mu2>0.2</mu2>
    </gazebo>
    <gazebo reference="panda_link3">
        <material>Gazebo/White</material>
        <mu1>0.2</mu1>
        <mu2>0.2</mu2>
    </gazebo>
    <gazebo reference="panda_link4">
        <material>Gazebo/White</material>
        <mu1>0.2</mu1>
        <mu2>0.2</mu2>
    </gazebo>
    <gazebo reference="panda_link5">
        <material>Gazebo/White</material>
        <mu1>0.2</mu1>
        <mu2>0.2</mu2>
    </gazebo>
    <gazebo reference="panda_link6">
        <material>Gazebo/White</material>
        <mu1>0.2</mu1>
        <mu2>0.2</mu2>
    </gazebo>
    <gazebo reference="panda_link7">
        <material>Gazebo/White</material>
        <mu1>0.2</mu1>
        <mu2>0.2</mu2>
    </gazebo>
    <gazebo reference="panda_link8">
        <material>Gazebo/White</material>
        <mu1>0.2</mu1>
        <mu2>0.2</mu2>
    </gazebo>
    <transmission name="panda_tran_1">
        <type>transmission_interface/SimpleTransmission</type>
        <joint name="panda_joint1">
            <hardwareInterface>hardware_interface/EffortJointInterface</hardwareInterface>
        </joint>
        <actuator name="panda_motor_1">
            <hardwareInterface>hardware_interface/EffortJointInterface</hardwareInterface>
            <mechanicalReduction>1</mechanicalReduction>
        </actuator>
    </transmission>
    <transmission name="panda_tran_2">
        <type>transmission_interface/SimpleTransmission</type>
        <joint name="panda_joint2">
            <hardwareInterface>hardware_interface/EffortJointInterface</hardwareInterface>
        </joint>
        <actuator name="panda_motor_2">
            <hardwareInterface>hardware_interface/EffortJointInterface</hardwareInterface>
            <mechanicalReduction>1</mechanicalReduction>
        </actuator>
    </transmission>
    <transmission name="panda_tran_3">
        <type>transmission_interface/SimpleTransmission</type>
        <joint name="panda_joint3">
            <hardwareInterface>hardware_interface/EffortJointInterface</hardwareInterface>
        </joint>
        <actuator name="panda_motor_3">
            <hardwareInterface>hardware_interface/EffortJointInterface</hardwareInterface>
            <mechanicalReduction>1</mechanicalReduction>
        </actuator>
    </transmission>
    <transmission name="panda_tran_4">
        <type>transmission_interface/SimpleTransmission</type>
        <joint name="panda_joint4">
            <hardwareInterface>hardware_interface/EffortJointInterface</hardwareInterface>
        </joint>
        <actuator name="panda_motor_4">
            <hardwareInterface>hardware_interface/EffortJointInterface</hardwareInterface>
            <mechanicalReduction>1</mechanicalReduction>
        </actuator>
    </transmission>
    <transmission name="panda_tran_5">
        <type>transmission_interface/SimpleTransmission</type>
        <joint name="panda_joint5">
            <hardwareInterface>hardware_interface/EffortJointInterface</hardwareInterface>
        </joint>
        <actuator name="panda_motor_5">
            <hardwareInterface>hardware_interface/EffortJointInterface</hardwareInterface>
            <mechanicalReduction>1</mechanicalReduction>
        </actuator>
    </transmission>
    <transmission name="panda_tran_6">
        <type>transmission_interface/SimpleTransmission</type>
        <joint name="panda_joint6">
            <hardwareInterface>hardware_interface/EffortJointInterface</hardwareInterface>
        </joint>
        <actuator name="panda_motor_6">
            <hardwareInterface>hardware_interface/EffortJointInterface</hardwareInterface>
            <mechanicalReduction>1</mechanicalReduction>
        </actuator>
    </transmission>
    <transmission name="panda_tran_7">
        <type>transmission_interface/SimpleTransmission</type>
        <joint name="panda_joint7">
            <hardwareInterface>hardware_interface/EffortJointInterface</hardwareInterface>
        </joint>
        <actuator name="panda_motor_7">
            <hardwareInterface>hardware_interface/EffortJointInterface</hardwareInterface>
            <mechanicalReduction>1</mechanicalReduction>
        </actuator>
    </transmission>
    <gazebo>
        <plugin filename="libgazebo_ros_control.so" name="gazebo_ros_control" />
    </gazebo>
    <joint name="panda_hand_joint" type="fixed">
        <parent link="panda_link8" />
        <child link="panda_hand" />
        <origin rpy="0 0 -0.7853981633974483" xyz="0 0 0" />
    </joint>
    <link name="panda_hand">
        <visual>
            <geometry>
                <mesh filename="package://franka_description/meshes/visual/hand.dae" />
            </geometry>
        </visual>
        <collision>
            <geometry>
                <mesh filename="package://franka_description/meshes/collision/hand.stl" />
            </geometry>
        </collision>
        <inertial>
            <origin rpy="0 0 0" xyz="0 0 0" />
            <mass value="0.48" />
            <inertia ixx="0.1" ixy="0.0" ixz="0.0" iyy="0.1" iyz="0.0" izz="0.1" />
        </inertial>
    </link>
    <link name="panda_leftfinger">
        <visual>
            <geometry>
                <mesh filename="package://franka_description/meshes/visual/finger.dae" />
            </geometry>
        </visual>
        <collision>
            <geometry>
                <mesh filename="package://franka_description/meshes/collision/finger.stl" />
            </geometry>
        </collision>
        <inertial>
            <origin rpy="0 0 0" xyz="0 0 0" />
            <mass value="0.1" />
            <inertia ixx="0.1" ixy="0.0" ixz="0.0" iyy="0.1" iyz="0.0" izz="0.1" />
        </inertial>
    </link>
    <link name="panda_rightfinger">
        <visual>
            <origin rpy="0 0 3.141592653589793" xyz="0 0 0" />
            <geometry>
                <mesh filename="package://franka_description/meshes/visual/finger.dae" />
            </geometry>
        </visual>
        <collision>
            <origin rpy="0 0 3.141592653589793" xyz="0 0 0" />
            <geometry>
                <mesh filename="package://franka_description/meshes/collision/finger.stl" />
            </geometry>
        </collision>
        <inertial>
            <origin rpy="0 0 3.141592653589793" xyz="0 0 0" />
            <mass value="0.1" />
            <inertia ixx="0.1" ixy="0.0" ixz="0.0" iyy="0.1" iyz="0.0" izz="0.1" />
        </inertial>
    </link>
    <joint name="panda_finger_joint1" type="prismatic">
        <parent link="panda_hand" />
        <child link="panda_leftfinger" />
        <origin rpy="0 0 0" xyz="0 0 0.0584" />
        <axis xyz="0 1 0" />
        <limit effort="150" lower="0.0" upper="0.04" velocity="0.2" />
    </joint>
    <joint name="panda_finger_joint2" type="prismatic">
        <parent link="panda_hand" />
        <child link="panda_rightfinger" />
        <origin rpy="0 0 0" xyz="0 0 0.0584" />
        <axis xyz="0 -1 0" />
        <limit effort="150" lower="0.0" upper="0.04" velocity="0.2" />
    </joint>
    <gazebo reference="panda_hand">
        <material>Gazebo/Grey</material>
        <mu1>50</mu1>
        <mu2>50</mu2>
        <maxVel>0.001</maxVel>
        <!-- Default: 0.01, Description: maximum contact correction velocity truncation term. -->
        <minDepth>0.001</minDepth>
        <!-- Default: 0.0 meter, Description: minimum allowable depth before contact correction impulse is applied -->
    </gazebo>
    <gazebo reference="panda_rightfinger">
        <material>Gazebo/Grey</material>
        <mu1>50</mu1>
        <mu2>50</mu2>
        <maxVel>0.001</maxVel>
        <!-- Default: 0.01, Description: maximum contact correction velocity truncation term. -->
        <minDepth>0.001</minDepth>
        <!-- Default: 0.0 meter, Description: minimum allowable depth before contact correction impulse is applied -->
    </gazebo>
    <gazebo reference="panda_leftfinger">
        <material>Gazebo/Grey</material>
        <mu1>50</mu1>
        <mu2>50</mu2>
        <maxVel>0.001</maxVel>
        <!-- Default: 0.01, Description: maximum contact correction velocity truncation term. -->
        <minDepth>0.001</minDepth>
        <!-- Default: 0.0 meter, Description: minimum allowable depth before contact correction impulse is applied -->
    </gazebo>
    <transmission name="panda_leftfinger">
        <type>transmission_interface/SimpleTransmission</type>
        <joint name="panda_finger_joint1">
            <hardwareInterface>hardware_interface/EffortJointInterface</hardwareInterface>
        </joint>
        <actuator name="panda_finger_joint1">
            <hardwareInterface>hardware_interface/EffortJointInterface</hardwareInterface>
            <mechanicalReduction>1</mechanicalReduction>
        </actuator>
    </transmission>
    <transmission name="panda_rightfinger">
        <type>transmission_interface/SimpleTransmission</type>
        <joint name="panda_finger_joint2">
            <hardwareInterface>hardware_interface/EffortJointInterface</hardwareInterface>
        </joint>
        <actuator name="panda_finger_joint2">
            <hardwareInterface>hardware_interface/EffortJointInterface</hardwareInterface>
            <mechanicalReduction>1</mechanicalReduction>
        </actuator>
    </transmission>
    <!-- Size of square 'camera' box -->
    <joint name="camera_joint" type="fixed">
        <axis xyz="0 1 0" />
        <origin rpy="0 1.57079 0" xyz="0.5 0 0.6" />
        <parent link="world" />
        <child link="camera_link" />
    </joint>
    <!-- Camera -->
    <link name="camera_link">
        <collision>
            <origin rpy="0 0 0" xyz="0 0 0" />
            <geometry>
                <box size="0.05 0.05 0.05" />
            </geometry>
        </collision>
        <visual>
            <origin rpy="0 0 0" xyz="0 0 0" />
            <geometry>
                <box size="0.05 0.05 0.05" />
            </geometry>
            <material name="red" />
        </visual>
        <inertial>
            <mass value="1e-5" />
            <origin rpy="0 0 0" xyz="0 0 0" />
            <inertia ixx="1e-6" ixy="0" ixz="0" iyy="1e-6" iyz="0" izz="1e-6" />
        </inertial>
    </link>
    <!-- Generate an optical frame http://www.ros.org/reps/rep-0103.html#suffix-frames
      so that ros and opencv can operate on the camera frame correctly -->
    <joint name="camera_optical_joint" type="fixed">
        <!-- these values have to be these values otherwise the gazebo camera image
        won't be aligned properly with the frame it is supposedly originating from -->
        <origin rpy="-1.5707963267948966 0 -1.5707963267948966" xyz="0 0 0" />
        <parent link="camera_link" />
        <child link="camera_link_optical" />
    </joint>
    <link name="camera_link_optical" />
    <!-- Camera_link -->
    <gazebo reference="camera_link">
        <mu1>0.2</mu1>
        <mu2>0.2</mu2>
        <material>Gazebo/Red</material>
    </gazebo>
    <!-- Camera -->
    <gazebo reference="camera_link">
        <sensor name="camera1" type="camera">
            <update_rate>30.0</update_rate>
            <camera name="2d_camera_head">
                <horizontal_fov>1.3962634</horizontal_fov>
                <image>
                    <width>640</width>
                    <height>480</height>
                    <format>R8G8B8</format>
                </image>
                <clip>
                    <near>0.02</near>
                    <far>300</far>
                </clip>
                <noise>
                    <type>gaussian</type>
                    <!-- Noise is sampled independently per pixel on each frame.
               That pixel's noise value is added to each of its color
               channels, which at that point lie in the range [0,1]. -->
                    <mean>0.0</mean>
                    <stddev>0.007</stddev>
                </noise>
            </camera>
            <plugin filename="libgazebo_ros_camera.so" name="camera_controller">
                <alwaysOn>true</alwaysOn>
                <updateRate>0.0</updateRate>
                <cameraName>/camera1</cameraName>
                <imageTopicName>image_raw</imageTopicName>
                <cameraInfoTopicName>camera_info</cameraInfoTopicName>
                <frameName>camera_link_optical</frameName>
                <!-- setting hackBaseline to anything but 0.0 will cause a misalignment
            between the gazebo sensor image and the frame it is supposed to
            be attached to -->
                <hackBaseline>0.0</hackBaseline>
                <distortionK1>0.0</distortionK1>
                <distortionK2>0.0</distortionK2>
                <distortionK3>0.0</distortionK3>
                <distortionT1>0.0</distortionT1>
                <distortionT2>0.0</distortionT2>
                <CxPrime>0</CxPrime>
                <Cx>0.0</Cx>
                <Cy>0.0</Cy>
                <focalLength>0.0</focalLength>
            </plugin>
        </sensor>
    </gazebo>
</robot>

